<?xml version="1.0" ?>
<robot name="wolfgang" version="1.0">
  <link name="base_link">
    <inertial>
      <origin rpy="0.0 0.0 0.0" xyz="0.0 0.0 0.0"/>
      <mass value="0.0001"/>
      <inertia ixx="0.0" ixy="0.0" ixz="0.0" iyy="0.0" iyz="0.0" izz="0.0"/>
    </inertial>
  </link>
  <joint name="base_link_to_base" type="fixed">
    <origin rpy="0.0 0.0 0.0" xyz="0.0 0.0 0.0"/>
    <parent link="base_link"/>
    <child link="torso"/>
  </joint>
  <link name="torso">
    <inertial>
      <origin rpy="0.0 0.0 0.0" xyz="-0.00564376 -0.0026297 0.109553"/>
      <mass value="2.0839"/>
      <inertia ixx="0.0183896" ixy="-6.80173e-05" ixz="-0.00140827" iyy="0.0158772" iyz="0.000104074" izz="0.00780317"/>
    </inertial>
    <visual>
      <origin rpy="-3.14159 1.5708 0.0" xyz="-0.0015 0.053 0.2035"/>
      <geometry>
        <mesh filename="package://wolfgang_description/urdf/mx-64-body.stl"/>
      </geometry>
      <material name="mx-64-body_material">
        <color rgba="0.647059 0.647059 0.647059 1.0"/>
      </material>
    </visual>
    <collision>
      <origin rpy="-3.14159 1.5708 0.0" xyz="0.01605 0.053 0.2035"/>
      <geometry>
        <box size="0.0402 0.041 0.0611"/>
      </geometry>
    </collision>
    <visual>
      <origin rpy="-1.2326e-32 -1.5708 0.0" xyz="-0.0015 -0.053 0.2035"/>
      <geometry>
        <mesh filename="package://wolfgang_description/urdf/mx-64-body.stl"/>
      </geometry>
      <material name="mx-64-body_material">
        <color rgba="0.647059 0.647059 0.647059 1.0"/>
      </material>
    </visual>
    <collision>
      <origin rpy="-1.2326e-32 -1.5708 0.0" xyz="0.01605 -0.053 0.2035"/>
      <geometry>
        <box size="0.0402 0.041 0.0611"/>
      </geometry>
    </collision>
    <visual>
      <origin rpy="0.0 -0.0 1.5708" xyz="-0.01485 -0.059 0.152"/>
      <geometry>
        <mesh filename="package://wolfgang_description/urdf/nuc_holder_right_front.stl"/>
      </geometry>
      <material name="nuc_holder_right_front_material">
        <color rgba="0.647059 0.647059 0.647059 1.0"/>
      </material>
    </visual>
    <visual>
      <origin rpy="-1.5708 6.08341e-17 1.5708" xyz="-0.057 0.077 0.213915"/>
      <geometry>
        <mesh filename="package://wolfgang_description/urdf/torso_bumper_right.stl"/>
      </geometry>
      <material name="torso_bumper_right_material">
        <color rgba="0.647059 0.647059 0.647059 1.0"/>
      </material>
    </visual>
    <collision>
      <origin rpy="-1.5708 6.08341e-17 1.5708" xyz="-0.0635 0.0675 0.177415"/>
      <geometry>
        <box size="0.019 0.073 0.013"/>
      </geometry>
    </collision>
    <collision>
      <origin rpy="2.25876 6.08341e-17 1.5708" xyz="-0.0831853 0.0675 0.193936"/>
      <geometry>
        <box size="0.019 0.0468795 0.005"/>
      </geometry>
    </collision>
    <collision>
      <origin rpy="-2.25876 6.08341e-17 1.5708" xyz="-0.0831853 0.0675 0.160894"/>
      <geometry>
        <box size="0.019 0.0468795 0.005"/>
      </geometry>
    </collision>
    <visual>
      <origin rpy="-5.55112e-17 8.2173e-33 -1.5708" xyz="-0.01 0.001 0.118"/>
      <geometry>
        <mesh filename="package://wolfgang_description/urdf/core.stl"/>
      </geometry>
      <material name="core_material">
        <color rgba="0.647059 0.647059 0.647059 1.0"/>
      </material>
    </visual>
    <visual>
      <origin rpy="-5.55112e-17 5.55112e-17 -1.5708" xyz="-0.0175 -0.0035 0.0295"/>
      <geometry>
        <mesh filename="package://wolfgang_description/urdf/battery.stl"/>
      </geometry>
      <material name="battery_material">
        <color rgba="0.647059 0.647059 0.647059 1.0"/>
      </material>
    </visual>
    <collision>
      <origin rpy="-5.55112e-17 5.55112e-17 -1.5708" xyz="-0.0375 -0.0035 0.0295"/>
      <geometry>
        <box size="0.14 0.04 0.044"/>
      </geometry>
    </collision>
    <visual>
      <origin rpy="1.5708 -0.0 -1.5708" xyz="0.0 -0.055 0.026"/>
      <geometry>
        <mesh filename="package://wolfgang_description/urdf/mx-106_body.stl"/>
      </geometry>
      <material name="mx-106_body_material">
        <color rgba="0.647059 0.647059 0.647059 1.0"/>
      </material>
    </visual>
    <collision>
      <origin rpy="1.5708 -0.0 -1.5708" xyz="0.01805 -0.055 0.026"/>
      <geometry>
        <box size="0.0402 0.046 0.0651"/>
      </geometry>
    </collision>
    <visual>
      <origin rpy="-1.5708 -6.08341e-17 -1.5708" xyz="0.053 0.077 0.213915"/>
      <geometry>
        <mesh filename="package://wolfgang_description/urdf/torso_bumper_left.stl"/>
      </geometry>
      <material name="torso_bumper_left_material">
        <color rgba="0.647059 0.647059 0.647059 1.0"/>
      </material>
    </visual>
    <collision>
      <origin rpy="-1.5708 -6.08341e-17 -1.5708" xyz="0.0595 0.0675 0.177415"/>
      <geometry>
        <box size="0.019 0.073 0.013"/>
      </geometry>
    </collision>
    <collision>
      <origin rpy="2.25876 -6.08341e-17 -1.5708" xyz="0.0791853 0.0675 0.193936"/>
      <geometry>
        <box size="0.019 0.0468795 0.005"/>
      </geometry>
    </collision>
    <collision>
      <origin rpy="-2.25876 -6.08341e-17 -1.5708" xyz="0.0791853 0.0675 0.160894"/>
      <geometry>
        <box size="0.019 0.0468795 0.005"/>
      </geometry>
    </collision>
    <visual>
      <origin rpy="1.11022e-16 1.0261e-16 1.5708" xyz="-0.04715 -0.0589 0.152"/>
      <geometry>
        <mesh filename="package://wolfgang_description/urdf/nuc_holder_right_back.stl"/>
      </geometry>
      <material name="nuc_holder_right_back_material">
        <color rgba="0.647059 0.647059 0.647059 1.0"/>
      </material>
    </visual>
    <visual>
      <origin rpy="1.5708 -0.0 -1.5708" xyz="-2.2754e-16 0.055 0.026"/>
      <geometry>
        <mesh filename="package://wolfgang_description/urdf/mx-106_body.stl"/>
      </geometry>
      <material name="mx-106_body_material">
        <color rgba="0.647059 0.647059 0.647059 1.0"/>
      </material>
    </visual>
    <collision>
      <origin rpy="1.5708 -0.0 -1.5708" xyz="0.01805 0.055 0.026"/>
      <geometry>
        <box size="0.0402 0.046 0.0651"/>
      </geometry>
    </collision>
    <visual>
      <origin rpy="0.0 -0.0 1.5708" xyz="-0.0375 -0.00925 0.0295"/>
      <geometry>
        <mesh filename="package://wolfgang_description/urdf/battery_clip.stl"/>
      </geometry>
      <material name="battery_clip_material">
        <color rgba="0.647059 0.647059 0.647059 1.0"/>
      </material>
    </visual>
    <visual>
      <origin rpy="1.11022e-16 1.0261e-16 1.5708" xyz="-0.04715 0.0359 0.149"/>
      <geometry>
        <mesh filename="package://wolfgang_description/urdf/nuc_holder_left_back.stl"/>
      </geometry>
      <material name="nuc_holder_left_back_material">
        <color rgba="0.647059 0.647059 0.647059 1.0"/>
      </material>
    </visual>

    <visual>
      <origin rpy="-3.14159 1.5708 0.0" xyz="-0.0015 -0.036 0.2035"/>
      <geometry>
        <mesh filename="package://wolfgang_description/urdf/imu_holder.stl"/>
      </geometry>
      <material name="imu_holder_material">
        <color rgba="0.647059 0.647059 0.647059 1.0"/>
      </material>
    </visual>
    <visual>
      <origin rpy="0.0 -0.0 0.0" xyz="-0.062 0.075 0.003"/>
      <geometry>
        <mesh filename="package://wolfgang_description/urdf/torso_bottom.stl"/>
      </geometry>
      <material name="torso_bottom_material">
        <color rgba="0.647059 0.647059 0.647059 1.0"/>
      </material>
    </visual>
    <collision>
      <origin rpy="0.0 -0.0 0.0" xyz="-0.002 6.93889e-17 0.043"/>
      <geometry>
        <box size="0.12 0.15 0.08"/>
      </geometry>
    </collision>
    <visual>
      <origin rpy="-1.5708 -0.0 1.5708" xyz="-0.0095 2.94903e-16 0.211"/>
      <geometry>
        <mesh filename="package://wolfgang_description/urdf/mx-64-body.stl"/>
      </geometry>
      <material name="mx-64-body_material">
        <color rgba="0.647059 0.647059 0.647059 1.0"/>
      </material>
    </visual>
    <collision>
      <origin rpy="-1.5708 -0.0 1.5708" xyz="0.00805 2.94903e-16 0.211"/>
      <geometry>
        <box size="0.0402 0.041 0.0611"/>
      </geometry>
    </collision>
    <visual>
      <origin rpy="-1.5708 -6.08341e-17 1.5708" xyz="-0.057 -0.077 0.213915"/>
      <geometry>
        <mesh filename="package://wolfgang_description/urdf/torso_bumper_left.stl"/>
      </geometry>
      <material name="torso_bumper_left_material">
        <color rgba="0.647059 0.647059 0.647059 1.0"/>
      </material>
    </visual>
    <collision>
      <origin rpy="-1.5708 -6.08341e-17 1.5708" xyz="-0.0635 -0.0675 0.177415"/>
      <geometry>
        <box size="0.019 0.073 0.013"/>
      </geometry>
    </collision>
    <collision>
      <origin rpy="2.25876 -6.08341e-17 1.5708" xyz="-0.0831853 -0.0675 0.193936"/>
      <geometry>
        <box size="0.019 0.0468795 0.005"/>
      </geometry>
    </collision>
    <collision>
      <origin rpy="-2.25876 -6.08341e-17 1.5708" xyz="-0.0831853 -0.0675 0.160894"/>
      <geometry>
        <box size="0.019 0.0468795 0.005"/>
      </geometry>
    </collision>
    <visual>
      <origin rpy="0.0 -0.0 1.5708" xyz="0.03 5.89806e-17 0.006"/>
      <geometry>
        <mesh filename="package://wolfgang_description/urdf/speaker_holder.stl"/>
      </geometry>
      <material name="speaker_holder_material">
        <color rgba="0.647059 0.647059 0.647059 1.0"/>
      </material>
    </visual>
    <visual>
      <origin rpy="1.11022e-16 2.83582e-16 1.5708" xyz="-0.002 -0.0115 0.152"/>
      <geometry>
        <mesh filename="package://wolfgang_description/urdf/nuc_main.stl"/>
      </geometry>
      <material name="nuc_main_material">
        <color rgba="0.647059 0.647059 0.647059 1.0"/>
      </material>
    </visual>
    <visual>
      <origin rpy="-1.5708 6.08341e-17 -1.5708" xyz="0.053 -0.077 0.213915"/>
      <geometry>
        <mesh filename="package://wolfgang_description/urdf/torso_bumper_right.stl"/>
      </geometry>
      <material name="torso_bumper_right_material">
        <color rgba="0.647059 0.647059 0.647059 1.0"/>
      </material>
    </visual>
    <collision>
      <origin rpy="-1.5708 6.08341e-17 -1.5708" xyz="0.0595 -0.0675 0.177415"/>
      <geometry>
        <box size="0.019 0.073 0.013"/>
      </geometry>
    </collision>
    <collision>
      <origin rpy="2.25876 6.08341e-17 -1.5708" xyz="0.0791853 -0.0675 0.193936"/>
      <geometry>
        <box size="0.019 0.0468795 0.005"/>
      </geometry>
    </collision>
    <collision>
      <origin rpy="-2.25876 6.08341e-17 -1.5708" xyz="0.0791853 -0.0675 0.160894"/>
      <geometry>
        <box size="0.019 0.0468795 0.005"/>
      </geometry>
    </collision>
    <visual>
      <origin rpy="0.0 -0.0 1.5708" xyz="-0.077 -0.075 0.083"/>
      <geometry>
        <mesh filename="package://wolfgang_description/urdf/torso_top.stl"/>
      </geometry>
      <material name="torso_top_material">
        <color rgba="0.647059 0.647059 0.647059 1.0"/>
      </material>
    </visual>
    <visual>
      <origin rpy="-5.55112e-17 -1.64346e-32 -1.5708" xyz="-0.002 -3.19189e-16 0.088"/>
      <geometry>
        <mesh filename="package://wolfgang_description/urdf/baseplate_odroid_xu4_core.stl"/>
      </geometry>
      <material name="baseplate_odroid_xu4_core_material">
        <color rgba="0.647059 0.647059 0.647059 1.0"/>
      </material>
    </visual>
    <collision>
      <origin rpy="0.0 -0.0 1.5708" xyz="-0.0045 2.498e-16 0.1405"/>
      <geometry>
        <box size="0.15 0.125 0.115"/>
      </geometry>
    </collision>
    <collision>
      <origin rpy="0.0923293 -0.0 1.5708" xyz="0.053 2.498e-16 0.115383"/>
      <geometry>
        <box size="0.15 0.01 0.0547657"/>
      </geometry>
    </collision>
    <collision>
      <origin rpy="0.0 -0.0 1.5708" xyz="0.058 2.498e-16 0.175725"/>
      <geometry>
        <box size="0.15 0.01 0.0654503"/>
      </geometry>
    </collision>
    <collision>
      <origin rpy="0.0 -0.0 1.5708" xyz="-0.005 2.498e-16 0.2155"/>
      <geometry>
        <box size="0.15 0.136 0.035"/>
      </geometry>
    </collision>
    <visual>
      <origin rpy="0.0 -0.0 1.5708" xyz="0.0314886 3.95288e-17 0.011"/>
      <geometry>
        <mesh filename="package://wolfgang_description/urdf/dummy_speaker.stl"/>
      </geometry>
      <material name="dummy_speaker_material">
        <color rgba="0.647059 0.647059 0.647059 1.0"/>
      </material>
    </visual>
    <visual>
      <origin rpy="0.0 -0.0 1.5708" xyz="-0.01485 0.036 0.149"/>
      <geometry>
        <mesh filename="package://wolfgang_description/urdf/nuc_holder_left_front.stl"/>
      </geometry>
      <material name="nuc_holder_left_front_material">
        <color rgba="0.647059 0.647059 0.647059 1.0"/>
      </material>
    </visual>
    <visual>
      <origin rpy="0.0 -0.0 1.5708" xyz="-0.0375 -0.00925 0.0295"/>
      <geometry>
        <mesh filename="package://wolfgang_description/urdf/battery_cage.stl"/>
      </geometry>
      <material name="battery_cage_material">
        <color rgba="0.4 0.4 0.4 1.0"/>
      </material>
    </visual>
  </link>
  <link name="imu_frame">
    <inertial>
      <origin rpy="0.0 0.0 0.0" xyz="0.0 0.0 0.0"/>
      <mass value="1e-09"/>
      <inertia ixx="0.0" ixy="0.0" ixz="0.0" iyy="0.0" iyz="0.0" izz="0.0"/>
    </inertial>
  </link>
  <joint name="imu_frame_frame" type="fixed">
    <origin rpy="5.31321e-16 -3.12873e-17 4.65401e-17" xyz="-0.0369749 -0.0474614 0.224"/>
    <axis xyz="0.0 0.0 0.0"/>
    <parent link="torso"/>
    <child link="imu_frame"/>
  </joint>
  <link name="r_shoulder">
    <inertial>
      <origin rpy="0.0 0.0 0.0" xyz="-0.0135397 0.0284022 -1.54699e-06"/>
      <mass value="0.041445"/>
      <inertia ixx="1.85473e-05" ixy="7.63058e-06" ixz="-9.41386e-10" iyy="2.76649e-05" iyz="8.71825e-10" izz="3.49573e-05"/>
    </inertial>
    <visual>
      <origin rpy="-1.5708 2.89513e-24 1.5708" xyz="-0.02595 0.042 2.77556e-17"/>
      <geometry>
        <mesh filename="package://wolfgang_description/urdf/sea_connector.stl"/>
      </geometry>
      <material name="sea_connector_material">
        <color rgba="0.717647 0.717647 0.717647 1.0"/>
      </material>
    </visual>
    <collision>
      <origin rpy="-1.5708 2.89513e-24 1.5708" xyz="-0.02845 0.042 2.78944e-17"/>
      <geometry>
        <cylinder length="0.005" radius="0.025"/>
      </geometry>
    </collision>
    <visual>
      <origin rpy="-1.5708 2.89513e-24 1.5708" xyz="-0.01695 0.042 8.32667e-17"/>
      <geometry>
        <mesh filename="package://wolfgang_description/urdf/sea_ninjaflex.stl"/>
      </geometry>
      <material name="sea_ninjaflex_material">
        <color rgba="0.717647 0.717647 0.717647 1.0"/>
      </material>
    </visual>
    <collision>
      <origin rpy="-1.5708 2.89513e-24 1.5708" xyz="-0.02145 0.042 8.35165e-17"/>
      <geometry>
        <cylinder length="0.009" radius="0.025"/>
      </geometry>
    </collision>
    <visual>
      <origin rpy="2.4048e-34 -1.72563e-31 -1.5783e-33" xyz="0.0 0.0 2.77556e-17"/>
      <geometry>
        <mesh filename="package://wolfgang_description/urdf/shoulder_connector.stl"/>
      </geometry>
      <material name="shoulder_connector_material">
        <color rgba="0.717647 0.717647 0.717647 1.0"/>
      </material>
    </visual>
    <collision>
      <origin rpy="2.4048e-34 -1.72563e-31 -1.5783e-33" xyz="-4.84753e-37 0.00075 2.77556e-17"/>
      <geometry>
        <box size="0.0639 0.0015 0.034"/>
      </geometry>
    </collision>
    <collision>
      <origin rpy="2.4048e-34 -1.72563e-31 -1.5783e-33" xyz="0.0312 0.0225 2.77556e-17"/>
      <geometry>
        <box size="0.0015 0.045 0.028"/>
      </geometry>
    </collision>
    <collision>
      <origin rpy="2.4048e-34 -1.72563e-31 -1.5783e-33" xyz="-0.0312 0.0225 2.77556e-17"/>
      <geometry>
        <box size="0.0015 0.045 0.028"/>
      </geometry>
    </collision>
  </link>
  <link name="r_upper_arm">
    <inertial>
      <origin rpy="0.0 0.0 0.0" xyz="9.77435e-05 -0.0325821 -0.0239229"/>
      <mass value="0.228498"/>
      <inertia ixx="0.000241455" ixy="8.09479e-07" ixz="7.57095e-08" iyy="0.000179491" iyz="-2.7985e-06" izz="0.000371127"/>
    </inertial>
    <visual>
      <origin rpy="-1.5708 4.16334e-16 -2.10942e-15" xyz="1.38778e-17 1.11022e-16 -0.0235"/>
      <geometry>
        <mesh filename="package://wolfgang_description/urdf/mx-64-body.stl"/>
      </geometry>
      <material name="mx-64-body_material">
        <color rgba="0.717647 0.717647 0.717647 1.0"/>
      </material>
    </visual>
    <collision>
      <origin rpy="-1.5708 4.16334e-16 -2.10942e-15" xyz="-2.31426e-17 -0.01755 -0.0235"/>
      <geometry>
        <box size="0.0402 0.041 0.0611"/>
      </geometry>
    </collision>
    <visual>
      <origin rpy="-1.5708 -1.5708 0.0" xyz="0.0265 -0.144 -0.0235"/>
      <geometry>
        <mesh filename="package://wolfgang_description/urdf/upper_arm.stl"/>
      </geometry>
      <material name="upper_arm_material">
        <color rgba="0.717647 0.717647 0.717647 1.0"/>
      </material>
    </visual>
    <collision>
      <origin rpy="-1.72085e-15 -1.5708 0.0" xyz="0.025125 -0.144 -0.0235"/>
      <geometry>
        <cylinder length="0.00225" radius="0.02"/>
      </geometry>
    </collision>
    <collision>
      <origin rpy="-1.72085e-15 -1.5708 0.0" xyz="0.025125 -0.014 -0.0235"/>
      <geometry>
        <cylinder length="0.00225" radius="0.02"/>
      </geometry>
    </collision>
    <collision>
      <origin rpy="-1.5708 -1.5708 0.0" xyz="0.025125 -0.079 -0.0235"/>
      <geometry>
        <box size="0.04 0.00225 0.13"/>
      </geometry>
    </collision>
    <visual>
      <origin rpy="-1.5708 -8.88178e-16 1.5708" xyz="-0.0147 -0.0105 -0.0235"/>
      <geometry>
        <mesh filename="package://wolfgang_description/urdf/connector_shoulder.stl"/>
      </geometry>
      <material name="connector_shoulder_material">
        <color rgba="0.717647 0.717647 0.717647 1.0"/>
      </material>
    </visual>
    <collision>
      <origin rpy="-1.5708 -8.88178e-16 1.5708" xyz="-0.01935 -0.0105 -0.0235"/>
      <geometry>
        <box size="0.036 0.04 0.0093"/>
      </geometry>
    </collision>
    <visual>
      <origin rpy="-1.5708 1.5708 0.0" xyz="-0.0265 -0.144 -0.0235"/>
      <geometry>
        <mesh filename="package://wolfgang_description/urdf/upper_arm.stl"/>
      </geometry>
      <material name="upper_arm_material">
        <color rgba="0.717647 0.717647 0.717647 1.0"/>
      </material>
    </visual>
    <collision>
      <origin rpy="1.88738e-15 1.5708 0.0" xyz="-0.025125 -0.144 -0.0235"/>
      <geometry>
        <cylinder length="0.00225" radius="0.02"/>
      </geometry>
    </collision>
    <collision>
      <origin rpy="1.88738e-15 1.5708 0.0" xyz="-0.025125 -0.014 -0.0235"/>
      <geometry>
        <cylinder length="0.00225" radius="0.02"/>
      </geometry>
    </collision>
    <collision>
      <origin rpy="-1.5708 1.5708 0.0" xyz="-0.025125 -0.079 -0.0235"/>
      <geometry>
        <box size="0.04 0.00225 0.13"/>
      </geometry>
    </collision>
    <visual>
      <origin rpy="1.5708 -8.88178e-16 1.5708" xyz="0.0147 -0.0105 -0.0235"/>
      <geometry>
        <mesh filename="package://wolfgang_description/urdf/connector_shoulder.stl"/>
      </geometry>
      <material name="connector_shoulder_material">
        <color rgba="0.717647 0.717647 0.717647 1.0"/>
      </material>
    </visual>
    <collision>
      <origin rpy="1.5708 -8.88178e-16 1.5708" xyz="0.01935 -0.0105 -0.0235"/>
      <geometry>
        <box size="0.036 0.04 0.0093"/>
      </geometry>
    </collision>
    <visual>
      <origin rpy="-1.72085e-15 -1.5708 0.0" xyz="0.024 -0.064 -0.038499"/>
      <geometry>
        <mesh filename="package://wolfgang_description/urdf/upper_arm_spacer.stl"/>
      </geometry>
      <material name="upper_arm_spacer_material">
        <color rgba="0.717647 0.717647 0.717647 1.0"/>
      </material>
    </visual>
    <collision>
      <origin rpy="-1.72085e-15 -1.5708 0.0" xyz="0.001 -0.0715 -0.023699"/>
      <geometry>
        <box size="0.0376 0.023 0.046"/>
      </geometry>
    </collision>
  </link>
  <link name="r_lower_arm">
    <inertial>
      <origin rpy="0.0 0.0 0.0" xyz="0.000436307 -0.0605126 -0.0235553"/>
      <mass value="0.207774"/>
      <inertia ixx="0.001088" ixy="-1.16188e-06" ixz="-5.01515e-09" iyy="8.90324e-05" iyz="-3.22666e-08" izz="0.00110076"/>
    </inertial>
    <visual>
      <origin rpy="-1.5708 -1.02349e-15 -3.14159" xyz="3.19189e-16 -0.163682 -0.0065"/>
      <geometry>
        <mesh filename="package://wolfgang_description/urdf/lower_arm.stl"/>
      </geometry>
      <material name="lower_arm_material">
        <color rgba="0.960784 0.960784 0.960784 1.0"/>
      </material>
    </visual>
    <collision>
      <origin rpy="-8.99281e-15 -1.02349e-15 -3.14159" xyz="3.19651e-16 -0.163682 -0.0055"/>
      <geometry>
        <cylinder length="0.002" radius="0.04"/>
      </geometry>
    </collision>
    <collision>
      <origin rpy="-1.5708 -1.02349e-15 -3.14159" xyz="0.0015 -0.0631823 -0.0055"/>
      <geometry>
        <box size="0.044 0.002 0.145"/>
      </geometry>
    </collision>
    <collision>
      <origin rpy="-8.99281e-15 -1.02349e-15 -3.14159" xyz="3.31308e-16 -0.193682 -0.0055"/>
      <geometry>
        <cylinder length="0.002" radius="0.032"/>
      </geometry>
    </collision>
    <collision>
      <origin rpy="-1.5708 -1.25729e-15 0.252688" xyz="-0.0282 -0.187682 -0.0055"/>
      <geometry>
        <box size="0.012 0.002 0.029"/>
      </geometry>
    </collision>
    <collision>
      <origin rpy="-1.5708 3.23926e-15 -0.252688" xyz="0.0282 -0.187682 -0.0055"/>
      <geometry>
        <box size="0.012 0.002 0.029"/>
      </geometry>
    </collision>
    <visual>
      <origin rpy="-1.5708 5.6205e-16 -5.30016e-31" xyz="0.0 -3.46945e-18 -0.0235"/>
      <geometry>
        <mesh filename="package://wolfgang_description/urdf/mx-64-body.stl"/>
      </geometry>
      <material name="mx-64-body_material">
        <color rgba="0.960784 0.960784 0.960784 1.0"/>
      </material>
    </visual>
    <collision>
      <origin rpy="-1.5708 5.6205e-16 -5.30016e-31" xyz="-1.94844e-18 -0.01755 -0.0235"/>
      <geometry>
        <box size="0.0402 0.041 0.0611"/>
      </geometry>
    </collision>
    <visual>
      <origin rpy="1.5708 1.84661e-15 9.4369e-16" xyz="2.70617e-16 -0.163682 -0.0065"/>
      <geometry>
        <mesh filename="package://wolfgang_description/urdf/hand.stl"/>
      </geometry>
      <material name="hand_material">
        <color rgba="0.960784 0.960784 0.960784 1.0"/>
      </material>
    </visual>
    <collision>
      <origin rpy="-3.14159 1.84661e-15 9.4369e-16" xyz="2.5077e-16 -0.163682 -0.0235"/>
      <geometry>
        <cylinder length="0.034" radius="0.04"/>
      </geometry>
    </collision>
    <collision>
      <origin rpy="-3.14159 1.84661e-15 9.4369e-16" xyz="2.82411e-16 -0.193682 -0.0235"/>
      <geometry>
        <cylinder length="0.034" radius="0.032"/>
      </geometry>
    </collision>
    <collision>
      <origin rpy="1.5708 -3.66153e-15 2.8889" xyz="0.0282 -0.187682 -0.0235"/>
      <geometry>
        <box size="0.012 0.034 0.029"/>
      </geometry>
    </collision>
    <collision>
      <origin rpy="1.5708 8.55892e-17 -2.8889" xyz="-0.0282 -0.187682 -0.0235"/>
      <geometry>
        <box size="0.012 0.034 0.029"/>
      </geometry>
    </collision>
    <visual>
      <origin rpy="-1.5708 -7.02563e-16 -3.14159" xyz="2.84495e-16 -0.163682 -0.0425"/>
      <geometry>
        <mesh filename="package://wolfgang_description/urdf/lower_arm.stl"/>
      </geometry>
      <material name="lower_arm_material">
        <color rgba="0.960784 0.960784 0.960784 1.0"/>
      </material>
    </visual>
    <collision>
      <origin rpy="-1.4988e-14 -7.02563e-16 -3.14159" xyz="2.84495e-16 -0.163682 -0.0415"/>
      <geometry>
        <cylinder length="0.002" radius="0.04"/>
      </geometry>
    </collision>
    <collision>
      <origin rpy="-1.5708 -7.02563e-16 -3.14159" xyz="0.0015 -0.0631823 -0.0415"/>
      <geometry>
        <box size="0.044 0.002 0.145"/>
      </geometry>
    </collision>
    <collision>
      <origin rpy="-1.4988e-14 -7.02563e-16 -3.14159" xyz="2.89491e-16 -0.193682 -0.0415"/>
      <geometry>
        <cylinder length="0.002" radius="0.032"/>
      </geometry>
    </collision>
    <collision>
      <origin rpy="-1.5708 -3.06687e-15 0.252688" xyz="-0.0282 -0.187682 -0.0415"/>
      <geometry>
        <box size="0.012 0.002 0.029"/>
      </geometry>
    </collision>
    <collision>
      <origin rpy="-1.5708 4.42737e-15 -0.252688" xyz="0.0282 -0.187682 -0.0415"/>
      <geometry>
        <box size="0.012 0.002 0.029"/>
      </geometry>
    </collision>
  </link>
  <link name="r_wrist">
    <inertial>
      <origin rpy="0.0 0.0 0.0" xyz="0.0 0.0 0.0"/>
      <mass value="1e-09"/>
      <inertia ixx="0.0" ixy="0.0" ixz="0.0" iyy="0.0" iyz="0.0" izz="0.0"/>
    </inertial>
  </link>
  <joint name="r_wrist_frame" type="fixed">
    <origin rpy="1.5708 7.31053e-15 -1.5708" xyz="3.1225e-16 -0.226182 -0.0235"/>
    <axis xyz="0.0 0.0 0.0"/>
    <parent link="r_lower_arm"/>
    <child link="r_wrist"/>
  </joint>
  <joint name="RElbow" type="revolute">
    <origin rpy="-1.5708 1.27676e-15 -1.5708" xyz="0.024 -0.144 -0.0235"/>
    <axis xyz="0.0 0.0 1.0"/>
    <parent link="r_upper_arm"/>
    <child link="r_lower_arm"/>
    <limit effort="7.3" lower="-1.0472" upper="1.5708" velocity="8.17"/>
    <dynamics damping="0.65" friction="1.73"/>
  </joint>
  <joint name="RShoulderRoll" type="revolute">
    <origin rpy="1.5708 8.32338e-16 -1.5708" xyz="-0.01695 0.042 0.0"/>
    <axis xyz="-0.0 -0.0 -1.0"/>
    <parent link="r_shoulder"/>
    <child link="r_upper_arm"/>
    <limit effort="7.3" lower="0.0" upper="3.14159" velocity="8.17"/>
    <dynamics damping="0.65" friction="1.73"/>
  </joint>
  <joint name="RShoulderPitch" type="revolute">
    <origin rpy="-4.34612e-17 1.66533e-15 -3.14159" xyz="-0.0015 -0.0765 0.2035"/>
    <axis xyz="-0.0 1.0 -0.0"/>
    <parent link="torso"/>
    <child link="r_shoulder"/>
    <limit effort="7.3" lower="-3.14159" upper="3.14159" velocity="8.17"/>
    <dynamics damping="0.65" friction="1.73"/>
  </joint>
  <link name="l_shoulder">
    <inertial>
      <origin rpy="0.0 0.0 0.0" xyz="-0.0135397 0.0284022 1.54699e-06"/>
      <mass value="0.041445"/>
      <inertia ixx="1.85473e-05" ixy="7.63058e-06" ixz="9.41386e-10" iyy="2.76649e-05" iyz="-8.71825e-10" izz="3.49573e-05"/>
    </inertial>
    <visual>
      <origin rpy="1.5708 2.69257e-16 -1.5708" xyz="-0.02595 0.042 -2.77556e-17"/>
      <geometry>
        <mesh filename="package://wolfgang_description/urdf/sea_connector.stl"/>
      </geometry>
      <material name="sea_connector_material">
        <color rgba="0.647059 0.647059 0.647059 1.0"/>
      </material>
    </visual>
    <collision>
      <origin rpy="1.5708 2.69257e-16 -1.5708" xyz="-0.02845 0.042 -2.77556e-17"/>
      <geometry>
        <cylinder length="0.005" radius="0.025"/>
      </geometry>
    </collision>
    <visual>
      <origin rpy="4.03198e-33 -5.25487e-46 -1.08705e-48" xyz="0.0 0.0 -2.77556e-17"/>
      <geometry>
        <mesh filename="package://wolfgang_description/urdf/shoulder_connector.stl"/>
      </geometry>
      <material name="shoulder_connector_material">
        <color rgba="0.647059 0.647059 0.647059 1.0"/>
      </material>
    </visual>
    <collision>
      <origin rpy="4.03198e-33 -5.25487e-46 -1.08705e-48" xyz="2.51309e-51 0.00075 -2.77556e-17"/>
      <geometry>
        <box size="0.0639 0.0015 0.034"/>
      </geometry>
    </collision>
    <collision>
      <origin rpy="4.03198e-33 -5.25487e-46 -1.08705e-48" xyz="0.0312 0.0225 -2.77556e-17"/>
      <geometry>
        <box size="0.0015 0.045 0.028"/>
      </geometry>
    </collision>
    <collision>
      <origin rpy="4.03198e-33 -5.25487e-46 -1.08705e-48" xyz="-0.0312 0.0225 -2.77556e-17"/>
      <geometry>
        <box size="0.0015 0.045 0.028"/>
      </geometry>
    </collision>
    <visual>
      <origin rpy="1.5708 3.67828e-16 -1.5708" xyz="-0.01695 0.042 -5.55112e-17"/>
      <geometry>
        <mesh filename="package://wolfgang_description/urdf/sea_ninjaflex.stl"/>
      </geometry>
      <material name="sea_ninjaflex_material">
        <color rgba="0.647059 0.647059 0.647059 1.0"/>
      </material>
    </visual>
    <collision>
      <origin rpy="1.5708 3.67828e-16 -1.5708" xyz="-0.02145 0.042 -5.83823e-17"/>
      <geometry>
        <cylinder length="0.009" radius="0.025"/>
      </geometry>
    </collision>
  </link>
  <link name="l_upper_arm">
    <inertial>
      <origin rpy="0.0 0.0 0.0" xyz="9.77435e-05 -0.0325821 -0.0239229"/>
      <mass value="0.228498"/>
      <inertia ixx="0.000241455" ixy="8.09479e-07" ixz="7.57095e-08" iyy="0.000179491" iyz="-2.7985e-06" izz="0.000371127"/>
    </inertial>
    <visual>
      <origin rpy="-1.5708 -4.38538e-15 -2.0118e-29" xyz="0.0 2.77556e-17 -0.0235"/>
      <geometry>
        <mesh filename="package://wolfgang_description/urdf/mx-64-body.stl"/>
      </geometry>
      <material name="mx-64-body_material">
        <color rgba="0.647059 0.647059 0.647059 1.0"/>
      </material>
    </visual>
    <collision>
      <origin rpy="-1.5708 -4.38538e-15 -2.0118e-29" xyz="5.82097e-17 -0.01755 -0.0235"/>
      <geometry>
        <box size="0.0402 0.041 0.0611"/>
      </geometry>
    </collision>
    <visual>
      <origin rpy="-1.5708 3.44169e-15 1.5708" xyz="-0.0147 -0.0105 -0.0235"/>
      <geometry>
        <mesh filename="package://wolfgang_description/urdf/connector_shoulder.stl"/>
      </geometry>
      <material name="connector_shoulder_material">
        <color rgba="0.647059 0.647059 0.647059 1.0"/>
      </material>
    </visual>
    <collision>
      <origin rpy="-1.5708 3.44169e-15 1.5708" xyz="-0.01935 -0.0105 -0.0235"/>
      <geometry>
        <box size="0.036 0.04 0.0093"/>
      </geometry>
    </collision>
    <visual>
      <origin rpy="1.5708 3.44169e-15 1.5708" xyz="0.0147 -0.0105 -0.0235"/>
      <geometry>
        <mesh filename="package://wolfgang_description/urdf/connector_shoulder.stl"/>
      </geometry>
      <material name="connector_shoulder_material">
        <color rgba="0.647059 0.647059 0.647059 1.0"/>
      </material>
    </visual>
    <collision>
      <origin rpy="1.5708 3.44169e-15 1.5708" xyz="0.01935 -0.0105 -0.0235"/>
      <geometry>
        <box size="0.036 0.04 0.0093"/>
      </geometry>
    </collision>
    <visual>
      <origin rpy="4.35589e-15 -1.5708 0.0" xyz="0.024 -0.064 -0.038499"/>
      <geometry>
        <mesh filename="package://wolfgang_description/urdf/upper_arm_spacer.stl"/>
      </geometry>
      <material name="upper_arm_spacer_material">
        <color rgba="0.647059 0.647059 0.647059 1.0"/>
      </material>
    </visual>
    <collision>
      <origin rpy="4.35589e-15 -1.5708 0.0" xyz="0.001 -0.0715 -0.023699"/>
      <geometry>
        <box size="0.0376 0.023 0.046"/>
      </geometry>
    </collision>
    <visual>
      <origin rpy="-1.5708 1.5708 0.0" xyz="-0.0265 -0.144 -0.0235"/>
      <geometry>
        <mesh filename="package://wolfgang_description/urdf/upper_arm.stl"/>
      </geometry>
      <material name="upper_arm_material">
        <color rgba="0.647059 0.647059 0.647059 1.0"/>
      </material>
    </visual>
    <collision>
      <origin rpy="-4.35589e-15 1.5708 0.0" xyz="-0.025125 -0.144 -0.0235"/>
      <geometry>
        <cylinder length="0.00225" radius="0.02"/>
      </geometry>
    </collision>
    <collision>
      <origin rpy="-4.35589e-15 1.5708 0.0" xyz="-0.025125 -0.014 -0.0235"/>
      <geometry>
        <cylinder length="0.00225" radius="0.02"/>
      </geometry>
    </collision>
    <collision>
      <origin rpy="-1.5708 1.5708 0.0" xyz="-0.025125 -0.079 -0.0235"/>
      <geometry>
        <box size="0.04 0.00225 0.13"/>
      </geometry>
    </collision>
    <visual>
      <origin rpy="-1.5708 -1.5708 0.0" xyz="0.0265 -0.144 -0.0235"/>
      <geometry>
        <mesh filename="package://wolfgang_description/urdf/upper_arm.stl"/>
      </geometry>
      <material name="upper_arm_material">
        <color rgba="0.647059 0.647059 0.647059 1.0"/>
      </material>
    </visual>
    <collision>
      <origin rpy="4.35589e-15 -1.5708 0.0" xyz="0.025125 -0.144 -0.0235"/>
      <geometry>
        <cylinder length="0.00225" radius="0.02"/>
      </geometry>
    </collision>
    <collision>
      <origin rpy="4.35589e-15 -1.5708 0.0" xyz="0.025125 -0.014 -0.0235"/>
      <geometry>
        <cylinder length="0.00225" radius="0.02"/>
      </geometry>
    </collision>
    <collision>
      <origin rpy="-1.5708 -1.5708 0.0" xyz="0.025125 -0.079 -0.0235"/>
      <geometry>
        <box size="0.04 0.00225 0.13"/>
      </geometry>
    </collision>
  </link>
  <link name="l_lower_arm">
    <inertial>
      <origin rpy="0.0 0.0 0.0" xyz="-0.000436306 -0.0605126 -0.0235553"/>
      <mass value="0.207774"/>
      <inertia ixx="0.001088" ixy="-1.14836e-05" ixz="5.01178e-09" iyy="8.90324e-05" iyz="-3.22666e-08" izz="0.00110076"/>
    </inertial>
    <visual>
      <origin rpy="-1.5708 1.77494e-30 1.26218e-29" xyz="0.0 -1.73472e-18 -0.0235"/>
      <geometry>
        <mesh filename="package://wolfgang_description/urdf/mx-64-body.stl"/>
      </geometry>
      <material name="mx-64-body_material">
        <color rgba="0.960784 0.960784 0.960784 1.0"/>
      </material>
    </visual>
    <collision>
      <origin rpy="-1.5708 1.77494e-30 1.26218e-29" xyz="6.42385e-29 -0.01755 -0.0235"/>
      <geometry>
        <box size="0.0402 0.041 0.0611"/>
      </geometry>
    </collision>
    <visual>
      <origin rpy="1.5708 -1.0102e-29 1.41995e-29" xyz="-6.93889e-18 -0.163682 -0.0405"/>
      <geometry>
        <mesh filename="package://wolfgang_description/urdf/lower_arm.stl"/>
      </geometry>
      <material name="lower_arm_material">
        <color rgba="0.960784 0.960784 0.960784 1.0"/>
      </material>
    </visual>
    <collision>
      <origin rpy="-3.14159 -1.0102e-29 1.41995e-29" xyz="-6.93889e-18 -0.163682 -0.0415"/>
      <geometry>
        <cylinder length="0.002" radius="0.04"/>
      </geometry>
    </collision>
    <collision>
      <origin rpy="1.5708 -1.0102e-29 1.41995e-29" xyz="-0.0015 -0.0631823 -0.0415"/>
      <geometry>
        <box size="0.044 0.002 0.145"/>
      </geometry>
    </collision>
    <collision>
      <origin rpy="-3.14159 -1.0102e-29 1.41995e-29" xyz="-1.19349e-17 -0.193682 -0.0415"/>
      <geometry>
        <cylinder length="0.002" radius="0.032"/>
      </geometry>
    </collision>
    <collision>
      <origin rpy="1.5708 -1.8682e-28 2.8889" xyz="0.0282 -0.187682 -0.0415"/>
      <geometry>
        <box size="0.012 0.002 0.029"/>
      </geometry>
    </collision>
    <collision>
      <origin rpy="1.5708 2.06383e-28 -2.8889" xyz="-0.0282 -0.187682 -0.0415"/>
      <geometry>
        <box size="0.012 0.002 0.029"/>
      </geometry>
    </collision>
    <visual>
      <origin rpy="-1.5708 1.65734e-29 -3.14159" xyz="-8.32667e-17 -0.163682 -0.0405"/>
      <geometry>
        <mesh filename="package://wolfgang_description/urdf/hand.stl"/>
      </geometry>
      <material name="hand_material">
        <color rgba="0.960784 0.960784 0.960784 1.0"/>
      </material>
    </visual>
    <collision>
      <origin rpy="-5.54302e-28 1.65734e-29 -3.14159" xyz="-8.32667e-17 -0.163682 -0.0235"/>
      <geometry>
        <cylinder length="0.034" radius="0.04"/>
      </geometry>
    </collision>
    <collision>
      <origin rpy="-5.54302e-28 1.65734e-29 -3.14159" xyz="-8.32667e-17 -0.193682 -0.0235"/>
      <geometry>
        <cylinder length="0.034" radius="0.032"/>
      </geometry>
    </collision>
    <collision>
      <origin rpy="-1.5708 -1.54627e-28 0.252688" xyz="-0.0282 -0.187682 -0.0235"/>
      <geometry>
        <box size="0.012 0.034 0.029"/>
      </geometry>
    </collision>
    <collision>
      <origin rpy="-1.5708 1.22533e-28 -0.252688" xyz="0.0282 -0.187682 -0.0235"/>
      <geometry>
        <box size="0.012 0.034 0.029"/>
      </geometry>
    </collision>
    <visual>
      <origin rpy="1.5708 -1.65734e-29 4.01294e-27" xyz="-6.245e-17 -0.163682 -0.0045"/>
      <geometry>
        <mesh filename="package://wolfgang_description/urdf/lower_arm.stl"/>
      </geometry>
      <material name="lower_arm_material">
        <color rgba="0.960784 0.960784 0.960784 1.0"/>
      </material>
    </visual>
    <collision>
      <origin rpy="-3.14159 -1.65734e-29 4.01294e-27" xyz="-6.245e-17 -0.163682 -0.0055"/>
      <geometry>
        <cylinder length="0.002" radius="0.04"/>
      </geometry>
    </collision>
    <collision>
      <origin rpy="1.5708 -1.65734e-29 4.01294e-27" xyz="-0.0015 -0.0631823 -0.0055"/>
      <geometry>
        <box size="0.044 0.002 0.145"/>
      </geometry>
    </collision>
    <collision>
      <origin rpy="-3.14159 -1.65734e-29 4.01294e-27" xyz="-7.24421e-17 -0.193682 -0.0055"/>
      <geometry>
        <cylinder length="0.002" radius="0.032"/>
      </geometry>
    </collision>
    <collision>
      <origin rpy="1.5708 -1.23201e-28 2.8889" xyz="0.0282 -0.187682 -0.0055"/>
      <geometry>
        <box size="0.012 0.002 0.029"/>
      </geometry>
    </collision>
    <collision>
      <origin rpy="1.5708 1.55295e-28 -2.8889" xyz="-0.0282 -0.187682 -0.0055"/>
      <geometry>
        <box size="0.012 0.002 0.029"/>
      </geometry>
    </collision>
  </link>
  <link name="l_wrist">
    <inertial>
      <origin rpy="0.0 0.0 0.0" xyz="0.0 0.0 0.0"/>
      <mass value="1e-09"/>
      <inertia ixx="0.0" ixy="0.0" ixz="0.0" iyy="0.0" iyz="0.0" izz="0.0"/>
    </inertial>
  </link>
  <joint name="l_wrist_frame" type="fixed">
    <origin rpy="-1.5708 1.69653e-16 -1.5708" xyz="-7.63278e-17 -0.225182 -0.0235"/>
    <axis xyz="0.0 0.0 0.0"/>
    <parent link="l_lower_arm"/>
    <child link="l_wrist"/>
  </joint>
  <joint name="LElbow" type="revolute">
    <origin rpy="-1.5708 3.08909e-14 1.5708" xyz="-0.024 -0.144 -0.0235"/>
    <axis xyz="0.0 0.0 1.0"/>
    <parent link="l_upper_arm"/>
    <child link="l_lower_arm"/>
    <limit effort="7.3" lower="-1.5708" upper="1.0472" velocity="8.17"/>
    <dynamics damping="0.65" friction="1.73"/>
  </joint>
  <joint name="LShoulderRoll" type="revolute">
    <origin rpy="-1.5708 -5.19331e-15 1.5708" xyz="-0.01695 0.042 -2.77556e-17"/>
    <axis xyz="-0.0 -0.0 -1.0"/>
    <parent link="l_shoulder"/>
    <child link="l_upper_arm"/>
    <limit effort="7.3" lower="-3.14159" upper="0.0" velocity="8.17"/>
    <dynamics damping="0.65" friction="1.73"/>
  </joint>
  <joint name="LShoulderPitch" type="revolute">
    <origin rpy="-3.14159 1.66533e-16 3.14159" xyz="-0.0015 0.0765 0.2035"/>
    <axis xyz="-0.0 1.0 -0.0"/>
    <parent link="torso"/>
    <child link="l_shoulder"/>
    <limit effort="7.3" lower="-3.14159" upper="3.14159" velocity="8.17"/>
    <dynamics damping="0.65" friction="1.73"/>
  </joint>
  <link name="r_hip_1">
    <inertial>
      <origin rpy="0.0 0.0 0.0" xyz="1.20984e-11 0.010315 -1.06799e-07"/>
      <mass value="0.0689735"/>
      <inertia ixx="2.18955e-05" ixy="-2.44475e-14" ixz="3.06793e-15" iyy="0.00010714" iyz="-6.56688e-11" izz="0.000110523"/>
    </inertial>
    <visual>
      <origin rpy="-5.5278e-33 -0.0 0.0" xyz="0.0 -0.0006 -0.018"/>
      <geometry>
        <mesh filename="package://wolfgang_description/urdf/hip_u_connector.stl"/>
      </geometry>
      <material name="hip_u_connector_material">
        <color rgba="0.647059 0.647059 0.647059 1.0"/>
      </material>
    </visual>
    <collision>
      <origin rpy="-1.5708 1.5708 0.0" xyz="0.0 0.0014 3.46945e-18"/>
      <geometry>
        <box size="0.036 0.1 0.004"/>
      </geometry>
    </collision>
    <collision>
      <origin rpy="-1.5708 1.5708 0.0" xyz="-0.048 0.0259 3.46945e-18"/>
      <geometry>
        <box size="0.0260229 0.004 0.053"/>
      </geometry>
    </collision>
    <collision>
      <origin rpy="-1.5708 1.5708 0.0" xyz="0.048 0.0259 3.46945e-18"/>
      <geometry>
        <box size="0.0260229 0.004 0.053"/>
      </geometry>
    </collision>
    <collision>
      <origin rpy="-1.5708 1.5708 0.0" xyz="0.0 -0.0006 0.002"/>
      <geometry>
        <cylinder length="0.004" radius="0.025"/>
      </geometry>
    </collision>
  </link>
  <link name="r_hip_2">
    <inertial>
      <origin rpy="0.0 0.0 0.0" xyz="1.38724e-05 -0.0155281 -0.0486407"/>
      <mass value="0.319807"/>
      <inertia ixx="0.000268627" ixy="6.08561e-08" ixz="6.67248e-07" iyy="0.000268049" iyz="3.87608e-06" izz="0.000121331"/>
    </inertial>
    <visual>
      <origin rpy="-1.5708 4.34181e-16 -6.8556e-16" xyz="6.93889e-18 0.0 -0.026"/>
      <geometry>
        <mesh filename="package://wolfgang_description/urdf/mx-106_body.stl"/>
      </geometry>
      <material name="mx-106_body_material">
        <color rgba="0.262745 0.282353 0.301961 1.0"/>
      </material>
    </visual>
    <collision>
      <origin rpy="-1.5708 4.34181e-16 -6.8556e-16" xyz="-4.16733e-18 -0.01805 -0.026"/>
      <geometry>
        <box size="0.0402 0.046 0.0651"/>
      </geometry>
    </collision>
    <visual>
      <origin rpy="-3.14159 -3.01408e-17 1.5708" xyz="-0.0145 -0.021 -0.043"/>
      <geometry>
        <mesh filename="package://wolfgang_description/urdf/motor_connector.stl"/>
      </geometry>
      <material name="motor_connector_material">
        <color rgba="0.262745 0.282353 0.301961 1.0"/>
      </material>
    </visual>
    <collision>
      <origin rpy="-3.14159 -3.01408e-17 1.5708" xyz="-0.0175 -0.007 -0.04585"/>
      <geometry>
        <box size="0.028 0.006 0.0057"/>
      </geometry>
    </collision>
    <collision>
      <origin rpy="-3.14159 -3.01408e-17 1.5708" xyz="-0.01875 -0.007 -0.05165"/>
      <geometry>
        <box size="0.028 0.0035 0.0059"/>
      </geometry>
    </collision>
    <visual>
      <origin rpy="2.03474e-16 7.21579e-17 -3.14159" xyz="0.014 0.0105 -0.0892"/>
      <geometry>
        <mesh filename="package://wolfgang_description/urdf/thrustbearingholder.stl"/>
      </geometry>
      <material name="thrustbearingholder_material">
        <color rgba="0.262745 0.282353 0.301961 1.0"/>
      </material>
    </visual>
    <visual>
      <origin rpy="-3.14159 -2.1475e-16 -1.5708" xyz="0.0145 0.007 -0.043"/>
      <geometry>
        <mesh filename="package://wolfgang_description/urdf/motor_connector.stl"/>
      </geometry>
      <material name="motor_connector_material">
        <color rgba="0.262745 0.282353 0.301961 1.0"/>
      </material>
    </visual>
    <collision>
      <origin rpy="-3.14159 -2.1475e-16 -1.5708" xyz="0.0175 -0.007 -0.04585"/>
      <geometry>
        <box size="0.028 0.006 0.0057"/>
      </geometry>
    </collision>
    <collision>
      <origin rpy="-3.14159 -2.1475e-16 -1.5708" xyz="0.01875 -0.007 -0.05165"/>
      <geometry>
        <box size="0.028 0.0035 0.0059"/>
      </geometry>
    </collision>
    <visual>
      <origin rpy="-1.5708 -1.5708 0.0" xyz="-4.44089e-15 -1.11022e-16 -0.0691"/>
      <geometry>
        <mesh filename="package://wolfgang_description/urdf/mx-106_body.stl"/>
      </geometry>
      <material name="mx-106_body_material">
        <color rgba="0.262745 0.282353 0.301961 1.0"/>
      </material>
    </visual>
    <collision>
      <origin rpy="-1.5708 -1.5708 0.0" xyz="-4.45282e-15 -0.01805 -0.0691"/>
      <geometry>
        <box size="0.0402 0.046 0.0651"/>
      </geometry>
    </collision>
  </link>
  <link name="r_upper_leg">
    <visual>
      <origin xyz="0 -0.01295 -0.111994" rpy="-0.261799 0 0"/>
      <geometry>
        <box size="0.07 0.037 0.104"/>
      </geometry>
    </visual>
    <collision>
      <origin xyz="0 -0.01295 -0.111994" rpy="-0.261799 0 0"/>
      <geometry>
        <box size="0.07 0.037 0.104"/>
      </geometry>
    </collision>
    <visual>
      <origin xyz="-0.0375 0.022145 -0.04156" rpy="-0.261799 0 0"/>
      <geometry>
        <box size="0.005 0.065 0.05"/>
      </geometry>
    </visual>
    <collision>
      <origin xyz="-0.0375 0.022145 -0.04156" rpy="-0.261799 0 0"/>
      <geometry>
        <box size="0.005 0.065 0.05"/>
      </geometry>
    </collision>
    <visual>
      <origin xyz="0.0375 0.022145 -0.04156" rpy="-0.261799 0 0"/>
      <geometry>
        <box size="0.005 0.065 0.05"/>
      </geometry>
    </visual>
    <collision>
      <origin xyz="0.0375 0.022145 -0.04156" rpy="-0.261799 0 0"/>
      <geometry>
        <box size="0.005 0.065 0.05"/>
      </geometry>
    </collision>
  </link>
  <joint name="RKnee" type="revolute">
    <parent link="r_upper_leg"/>
    <child link="right_lower_leg"/>
    <axis xyz="1 0 0"/>
    <limit effort="10" lower="-0.3" upper="2.5" velocity="5.76"/>
    <origin xyz="0 0.01024 -0.204744" rpy="0.045988 0 0"/>
  </joint>
  <link name="right_lower_leg">
    <visual>
      <origin xyz="0 -0.00999 -0.05725" rpy="0.174533 0 0"/>
      <geometry>
        <box size="0.06 0.065 0.165"/>
      </geometry>
    </visual>
    <collision>
      <origin xyz="0 -0.00999 -0.05725" rpy="0.174533 0 0"/>
      <geometry>
        <box size="0.06 0.065 0.165"/>
      </geometry>
    </collision>
    <visual>
      <origin xyz="-0.0275 0.01951 -0.17225" rpy="0.174533 0 0"/>
      <geometry>
        <box size="0.005 0.065 0.065"/>
      </geometry>
    </visual>
    <collision>
      <origin xyz="-0.0275 0.01951 -0.17225" rpy="0.174533 0 0"/>
      <geometry>
        <box size="0.005 0.065 0.065"/>
      </geometry>
    </collision>
    <visual>
      <origin xyz="0.0275 0.01951 -0.17225" rpy="0.174533 0 0"/>
      <geometry>
        <box size="0.005 0.065 0.065"/>
      </geometry>
    </visual>
    <collision>
      <origin xyz="0.0275 0.01951 -0.17225" rpy="0.174533 0 0"/>
      <geometry>
        <box size="0.005 0.065 0.065"/>
      </geometry>
    </collision>
  </link>
  <joint name="RAnklePitch" type="revolute">
    <parent link="right_lower_leg"/>
    <child link="right_ankle"/>
    <axis xyz="-1 -0.000002 0"/>
    <limit effort="10" lower="-1.7" upper="1.7" velocity="5.76"/>
    <origin xyz="0 0.00001 -0.19975" rpy="-3.064387 0 -3.141591"/>
  </joint>
  <link name="right_ankle">
    <visual>
      <origin xyz="0 0.02 -0.0175" rpy="0 0 0"/>
      <geometry>
        <box size="0.04 0.08 0.065"/>
      </geometry>
    </visual>
    <collision>
      <origin xyz="0 0.02 -0.0175" rpy="0 0 0"/>
      <geometry>
        <box size="0.04 0.08 0.065"/>
      </geometry>
    </collision>
  </link>
  <joint name="RAnkleRoll" type="revolute">
    <parent link="right_ankle"/>
    <child link="right_foot [foot]"/>
    <axis xyz="0.000002 -1 0.000002"/>
    <limit effort="10" lower="-1.5" upper="1.5" velocity="5.76"/>
    <origin xyz="0 0.04 0" rpy="-3.141591 0.000004 -3.141591"/>
  </joint>
  <link name="right_foot [foot]">
    <visual>
      <origin xyz="-0.0105 0.037 -0.017" rpy="0 0 0"/>
      <geometry>
        <box size="0.125 0.0175 0.0585"/>
      </geometry>
    </visual>
    <collision>
      <origin xyz="-0.0105 0.037 -0.017" rpy="0 0 0"/>
      <geometry>
        <box size="0.125 0.0175 0.0585"/>
      </geometry>
    </collision>
    <visual>
      <origin xyz="-0.011 -0.128 -0.02" rpy="0 0 0"/>
      <geometry>
        <box size="0.125 0.08 0.05"/>
      </geometry>
    </visual>
    <collision>
      <origin xyz="-0.011 -0.128 -0.02" rpy="0 0 0"/>
      <geometry>
        <box size="0.125 0.08 0.05"/>
      </geometry>
    </collision>
    <visual>
      <origin xyz="-0.011 -0.028 -0.035" rpy="0 0 0"/>
      <geometry>
        <box size="0.125 0.12 0.01875"/>
      </geometry>
    </visual>
    <collision>
      <origin xyz="-0.011 -0.028 -0.035" rpy="0 0 0"/>
      <geometry>
        <box size="0.125 0.12 0.01875"/>
      </geometry>
    </collision>
  </link>
  <link name="right_touch_sensor_fl">
    <visual>
      <origin xyz="0 0 0.0056" rpy="3.110796 0 0"/>
      <geometry>
        <cylinder radius="0.009" length="0.001"/>
      </geometry>
    </visual>
    <collision>
      <origin xyz="0 0 0.0056" rpy="3.110796 0 0"/>
      <geometry>
        <cylinder radius="0.009" length="0.001"/>
      </geometry>
    </collision>
    <visual>
      <origin xyz="0 0.000015 0.0061" rpy="3.110796 0 0"/>
      <geometry>
        <sphere radius="0.009"/>
      </geometry>
    </visual>
    <collision>
      <origin xyz="0 0.000015 0.0061" rpy="3.110796 0 0"/>
      <geometry>
        <sphere radius="0.009"/>
      </geometry>
    </collision>
    <visual>
      <origin xyz="0 -0.000015 0.0051" rpy="3.110796 0 0"/>
      <geometry>
        <sphere radius="0.009"/>
      </geometry>
    </visual>
    <collision>
      <origin xyz="0 -0.000015 0.0051" rpy="3.110796 0 0"/>
      <geometry>
        <sphere radius="0.009"/>
      </geometry>
    </collision>
  </link>
  <link name="r_sole">
  </link>
  <joint name="r_sole_frame" type="fixed">
    <origin rpy="0.0 0.0 -1.5708" xyz="0.0 -0.05 -0.062"/>
    <axis xyz="0.0 0.0 0.0"/>
    <parent link="right_foot [foot]"/>
    <child link="r_sole"/>
  </joint>
  <joint name="right_foot [foot]_right_touch_sensor_fl_joint" type="fixed">
    <parent link="right_foot [foot]"/>
    <child link="right_touch_sensor_fl"/>
    <origin xyz="0.040899 -0.154143 -0.061056" rpy="0 0 0"/>
  </joint>
  <link name="right_touch_sensor_fr">
    <visual>
      <origin xyz="0 0 0.0056" rpy="3.110796 0 0"/>
      <geometry>
        <cylinder radius="0.009" length="0.001"/>
      </geometry>
    </visual>
    <collision>
      <origin xyz="0 0 0.0056" rpy="3.110796 0 0"/>
      <geometry>
        <cylinder radius="0.009" length="0.001"/>
      </geometry>
    </collision>
    <visual>
      <origin xyz="0 0.000015 0.0061" rpy="3.110796 0 0"/>
      <geometry>
        <sphere radius="0.009"/>
      </geometry>
    </visual>
    <collision>
      <origin xyz="0 0.000015 0.0061" rpy="3.110796 0 0"/>
      <geometry>
        <sphere radius="0.009"/>
      </geometry>
    </collision>
    <visual>
      <origin xyz="0 -0.000015 0.0051" rpy="3.110796 0 0"/>
      <geometry>
        <sphere radius="0.009"/>
      </geometry>
    </visual>
    <collision>
      <origin xyz="0 -0.000015 0.0051" rpy="3.110796 0 0"/>
      <geometry>
        <sphere radius="0.009"/>
      </geometry>
    </collision>
  </link>
  <joint name="right_foot [foot]_right_touch_sensor_fr_joint" type="fixed">
    <parent link="right_foot [foot]"/>
    <child link="right_touch_sensor_fr"/>
    <origin xyz="-0.0575 -0.154151 -0.061058" rpy="0 0 0"/>
  </joint>
  <link name="right_touch_sensor_bl">
    <visual>
      <origin xyz="0 0 0.0056" rpy="3.110796 0 0"/>
      <geometry>
        <cylinder radius="0.009" length="0.001"/>
      </geometry>
    </visual>
    <collision>
      <origin xyz="0 0 0.0056" rpy="3.110796 0 0"/>
      <geometry>
        <cylinder radius="0.009" length="0.001"/>
      </geometry>
    </collision>
    <visual>
      <origin xyz="0 0.000015 0.0061" rpy="3.110796 0 0"/>
      <geometry>
        <sphere radius="0.009"/>
      </geometry>
    </visual>
    <collision>
      <origin xyz="0 0.000015 0.0061" rpy="3.110796 0 0"/>
      <geometry>
        <sphere radius="0.009"/>
      </geometry>
    </collision>
    <visual>
      <origin xyz="0 -0.000015 0.0051" rpy="3.110796 0 0"/>
      <geometry>
        <sphere radius="0.009"/>
      </geometry>
    </visual>
    <collision>
      <origin xyz="0 -0.000015 0.0051" rpy="3.110796 0 0"/>
      <geometry>
        <sphere radius="0.009"/>
      </geometry>
    </collision>
  </link>
  <joint name="right_foot [foot]_right_touch_sensor_bl_joint" type="fixed">
    <parent link="right_foot [foot]"/>
    <child link="right_touch_sensor_bl"/>
    <origin xyz="0.041001 0.025012 -0.061061" rpy="0 0 0"/>
  </joint>
  <link name="right_touch_sensor_br">
    <visual>
      <origin xyz="0 0 0.0056" rpy="3.110796 0 0"/>
      <geometry>
        <cylinder radius="0.009" length="0.001"/>
      </geometry>
    </visual>
    <collision>
      <origin xyz="0 0 0.0056" rpy="3.110796 0 0"/>
      <geometry>
        <cylinder radius="0.009" length="0.001"/>
      </geometry>
    </collision>
    <visual>
      <origin xyz="0 0.000015 0.0061" rpy="3.110796 0 0"/>
      <geometry>
        <sphere radius="0.009"/>
      </geometry>
    </visual>
    <collision>
      <origin xyz="0 0.000015 0.0061" rpy="3.110796 0 0"/>
      <geometry>
        <sphere radius="0.009"/>
      </geometry>
    </collision>
    <visual>
      <origin xyz="0 -0.000015 0.0051" rpy="3.110796 0 0"/>
      <geometry>
        <sphere radius="0.009"/>
      </geometry>
    </visual>
    <collision>
      <origin xyz="0 -0.000015 0.0051" rpy="3.110796 0 0"/>
      <geometry>
        <sphere radius="0.009"/>
      </geometry>
    </collision>
  </link>
  <joint name="right_foot [foot]_right_touch_sensor_br_joint" type="fixed">
    <parent link="right_foot [foot]"/>
    <child link="right_touch_sensor_br"/>
    <origin xyz="-0.057499 0.025012 -0.061062" rpy="0 0 0"/>
  </joint>
  <link name="l_hip_1">
    <inertial>
      <origin rpy="0.0 0.0 0.0" xyz="1.20984e-11 0.010315 -1.06799e-07"/>
      <mass value="0.0689735"/>
      <inertia ixx="2.18955e-05" ixy="-2.44475e-14" ixz="3.06793e-15" iyy="0.00010714" iyz="-6.56688e-11" izz="0.000110523"/>
    </inertial>
    <visual>
      <origin rpy="0.0 -0.0 0.0" xyz="0.0 -0.0006 -0.018"/>
      <geometry>
        <mesh filename="package://wolfgang_description/urdf/hip_u_connector.stl"/>
      </geometry>
      <material name="hip_u_connector_material">
        <color rgba="0.647059 0.647059 0.647059 1.0"/>
      </material>
    </visual>
    <collision>
      <origin rpy="-1.5708 1.5708 0.0" xyz="0.0 0.0014 3.46945e-18"/>
      <geometry>
        <box size="0.036 0.1 0.004"/>
      </geometry>
    </collision>
    <collision>
      <origin rpy="-1.5708 1.5708 0.0" xyz="-0.048 0.0259 3.46945e-18"/>
      <geometry>
        <box size="0.0260229 0.004 0.053"/>
      </geometry>
    </collision>
    <collision>
      <origin rpy="-1.5708 1.5708 0.0" xyz="0.048 0.0259 3.46945e-18"/>
      <geometry>
        <box size="0.0260229 0.004 0.053"/>
      </geometry>
    </collision>
    <collision>
      <origin rpy="-1.5708 1.5708 0.0" xyz="0.0 -0.0006 0.002"/>
      <geometry>
        <cylinder length="0.004" radius="0.025"/>
      </geometry>
    </collision>
  </link>
  <link name="l_hip_2">
    <inertial>
      <origin rpy="0.0 0.0 0.0" xyz="-3.60783e-06 -0.0155281 -0.0486443"/>
      <mass value="0.319807"/>
      <inertia ixx="0.000268673" ixy="-7.40992e-08" ixz="-6.18751e-07" iyy="0.000268098" iyz="3.88325e-06" izz="0.000121333"/>
    </inertial>
    <visual>
      <origin rpy="-3.14159 1.52095e-16 -1.5708" xyz="0.0145 0.007 -0.043"/>
      <geometry>
        <mesh filename="package://wolfgang_description/urdf/motor_connector.stl"/>
      </geometry>
      <material name="motor_connector_material">
        <color rgba="0.647059 0.647059 0.647059 1.0"/>
      </material>
    </visual>
    <collision>
      <origin rpy="-3.14159 1.52095e-16 -1.5708" xyz="0.0175 -0.007 -0.04585"/>
      <geometry>
        <box size="0.028 0.006 0.0057"/>
      </geometry>
    </collision>
    <collision>
      <origin rpy="-3.14159 1.52095e-16 -1.5708" xyz="0.01875 -0.007 -0.05165"/>
      <geometry>
        <box size="0.028 0.0035 0.0059"/>
      </geometry>
    </collision>
    <visual>
      <origin rpy="-1.5708 -1.96517e-16 7.99616e-16" xyz="6.93889e-18 0.0 -0.026"/>
      <geometry>
        <mesh filename="package://wolfgang_description/urdf/mx-106_body.stl"/>
      </geometry>
      <material name="mx-106_body_material">
        <color rgba="0.647059 0.647059 0.647059 1.0"/>
      </material>
    </visual>
    <collision>
      <origin rpy="-1.5708 -1.96517e-16 7.99616e-16" xyz="-3.08152e-18 -0.01805 -0.026"/>
      <geometry>
        <box size="0.0402 0.046 0.0651"/>
      </geometry>
    </collision>
    <visual>
      <origin rpy="-1.5708 1.5708 0.0" xyz="2.08167e-17 -6.93889e-18 -0.0691"/>
      <geometry>
        <mesh filename="package://wolfgang_description/urdf/mx-106_body.stl"/>
      </geometry>
      <material name="mx-106_body_material">
        <color rgba="0.647059 0.647059 0.647059 1.0"/>
      </material>
    </visual>
    <collision>
      <origin rpy="-1.5708 1.5708 0.0" xyz="2.282e-17 -0.01805 -0.0691"/>
      <geometry>
        <box size="0.0402 0.046 0.0651"/>
      </geometry>
    </collision>
    <visual>
      <origin rpy="3.14159 -1.57669e-16 1.5708" xyz="-0.0145 -0.021 -0.043"/>
      <geometry>
        <mesh filename="package://wolfgang_description/urdf/motor_connector.stl"/>
      </geometry>
      <material name="motor_connector_material">
        <color rgba="0.647059 0.647059 0.647059 1.0"/>
      </material>
    </visual>
    <collision>
      <origin rpy="3.14159 -1.57669e-16 1.5708" xyz="-0.0175 -0.007 -0.04585"/>
      <geometry>
        <box size="0.028 0.006 0.0057"/>
      </geometry>
    </collision>
    <collision>
      <origin rpy="3.14159 -1.57669e-16 1.5708" xyz="-0.01875 -0.007 -0.05165"/>
      <geometry>
        <box size="0.028 0.0035 0.0059"/>
      </geometry>
    </collision>
    <visual>
      <origin rpy="-1.52095e-16 2.65906e-16 -3.14159" xyz="0.0151 0.0105 -0.0892"/>
      <geometry>
        <mesh filename="package://wolfgang_description/urdf/thrustbearingholder.stl"/>
      </geometry>
      <material name="thrustbearingholder_material">
        <color rgba="0.647059 0.647059 0.647059 1.0"/>
      </material>
    </visual>
  </link>
  <link name="l_upper_leg">
    <visual>
      <origin xyz="0 -0.01345 -0.102006" rpy="-0.261799 0 0"/>
      <geometry>
        <box size="0.07 0.037 0.104"/>
      </geometry>
    </visual>
    <collision>
      <origin xyz="0 -0.01345 -0.102006" rpy="-0.261799 0 0"/>
      <geometry>
        <box size="0.07 0.037 0.104"/>
      </geometry>
    </collision>
    <visual>
      <origin xyz="-0.0375 0.021645 -0.031572" rpy="-0.261799 0 0"/>
      <geometry>
        <box size="0.005 0.065 0.05"/>
      </geometry>
    </visual>
    <collision>
      <origin xyz="-0.0375 0.021645 -0.031572" rpy="-0.261799 0 0"/>
      <geometry>
        <box size="0.005 0.065 0.05"/>
      </geometry>
    </collision>
    <visual>
      <origin xyz="0.0375 0.021645 -0.031572" rpy="-0.261799 0 0"/>
      <geometry>
        <box size="0.005 0.065 0.05"/>
      </geometry>
    </visual>
    <collision>
      <origin xyz="0.0375 0.021645 -0.031572" rpy="-0.261799 0 0"/>
      <geometry>
        <box size="0.005 0.065 0.05"/>
      </geometry>
    </collision>
  </link>
  <joint name="LKnee" type="revolute">
    <parent link="l_upper_leg"/>
    <child link="left_lower_leg"/>
    <axis xyz="1 0 0"/>
    <limit effort="10" lower="-0.3" upper="2.5" velocity="5.76"/>
    <origin xyz="0 0.00924 -0.184766" rpy="0.046837 0 0"/>
  </joint>
  <link name="left_lower_leg">
    <visual>
      <origin xyz="0 -0.00999 -0.067253" rpy="0.174533 0 0"/>
      <geometry>
        <box size="0.06 0.065 0.165"/>
      </geometry>
    </visual>
    <collision>
      <origin xyz="0 -0.00999 -0.067253" rpy="0.174533 0 0"/>
      <geometry>
        <box size="0.06 0.065 0.165"/>
      </geometry>
    </collision>
    <visual>
      <origin xyz="-0.0275 0.01951 -0.182253" rpy="0.174533 0 0"/>
      <geometry>
        <box size="0.005 0.065 0.065"/>
      </geometry>
    </visual>
    <collision>
      <origin xyz="-0.0275 0.01951 -0.182253" rpy="0.174533 0 0"/>
      <geometry>
        <box size="0.005 0.065 0.065"/>
      </geometry>
    </collision>
    <visual>
      <origin xyz="0.0275 0.01951 -0.182253" rpy="0.174533 0 0"/>
      <geometry>
        <box size="0.005 0.065 0.065"/>
      </geometry>
    </visual>
    <collision>
      <origin xyz="0.0275 0.01951 -0.182253" rpy="0.174533 0 0"/>
      <geometry>
        <box size="0.005 0.065 0.065"/>
      </geometry>
    </collision>
  </link>
  <joint name="LAnklePitch" type="revolute">
    <parent link="left_lower_leg"/>
    <child link="left_ankle"/>
    <axis xyz="-1 -0.000002 0"/>
    <limit effort="10" lower="-1.7" upper="1.7" velocity="5.76"/>
    <origin xyz="0 0.00001 -0.209753" rpy="-3.061991 0 -3.141591"/>
  </joint>
  <link name="left_ankle">
    <visual>
      <origin xyz="0 0.02 -0.0175" rpy="0 0 0"/>
      <geometry>
        <box size="0.04 0.08 0.065"/>
      </geometry>
    </visual>
    <collision>
      <origin xyz="0 0.02 -0.0175" rpy="0 0 0"/>
      <geometry>
        <box size="0.04 0.08 0.065"/>
      </geometry>
    </collision>
  </link>
  <joint name="LAnkleRoll" type="revolute">
    <parent link="left_ankle"/>
    <child link="left_foot [foot]"/>
    <axis xyz="0.000002 -1 0.000002"/>
    <limit effort="10" lower="-1.5" upper="1.5" velocity="5.76"/>
    <origin xyz="0 0.04 0" rpy="-3.141591 -0.000005 -3.141591"/>
  </joint>
  <link name="left_foot [foot]">
    <visual>
      <origin xyz="0.0105 0.037 -0.017" rpy="0 0 0"/>
      <geometry>
        <box size="0.125 0.0175 0.0585"/>
      </geometry>
    </visual>
    <collision>
      <origin xyz="0.0105 0.037 -0.017" rpy="0 0 0"/>
      <geometry>
        <box size="0.125 0.0175 0.0585"/>
      </geometry>
    </collision>
    <visual>
      <origin xyz="0.011 -0.128 -0.02" rpy="0 0 0"/>
      <geometry>
        <box size="0.125 0.08 0.05"/>
      </geometry>
    </visual>
    <collision>
      <origin xyz="0.011 -0.128 -0.02" rpy="0 0 0"/>
      <geometry>
        <box size="0.125 0.08 0.05"/>
      </geometry>
    </collision>
    <visual>
      <origin xyz="0.011 -0.028 -0.035" rpy="0 0 0"/>
      <geometry>
        <box size="0.125 0.12 0.01875"/>
      </geometry>
    </visual>
    <collision>
      <origin xyz="0.011 -0.028 -0.035" rpy="0 0 0"/>
      <geometry>
        <box size="0.125 0.12 0.01875"/>
      </geometry>
    </collision>
  </link>
  <link name="left_touch_sensor_fr">
    <visual>
      <origin xyz="0 0 0.0056" rpy="3.110796 0 0"/>
      <geometry>
        <cylinder radius="0.009" length="0.001"/>
      </geometry>
    </visual>
    <collision>
      <origin xyz="0 0 0.0056" rpy="3.110796 0 0"/>
      <geometry>
        <cylinder radius="0.009" length="0.001"/>
      </geometry>
    </collision>
    <visual>
      <origin xyz="0 0.000015 0.0061" rpy="3.110796 0 0"/>
      <geometry>
        <sphere radius="0.009"/>
      </geometry>
    </visual>
    <collision>
      <origin xyz="0 0.000015 0.0061" rpy="3.110796 0 0"/>
      <geometry>
        <sphere radius="0.009"/>
      </geometry>
    </collision>
    <visual>
      <origin xyz="0 -0.000015 0.0051" rpy="3.110796 0 0"/>
      <geometry>
        <sphere radius="0.009"/>
      </geometry>
    </visual>
    <collision>
      <origin xyz="0 -0.000015 0.0051" rpy="3.110796 0 0"/>
      <geometry>
        <sphere radius="0.009"/>
      </geometry>
    </collision>
  </link>
  <link name="l_sole">
  </link>
  <joint name="l_sole_frame" type="fixed">
    <origin rpy="0.0 0.0 -1.5708" xyz="0.0 -0.05 -0.062"/>
    <axis xyz="0.0 0.0 0.0"/>
    <parent link="left_foot [foot]"/>
    <child link="l_sole"/>
  </joint>
  <joint name="left_foot [foot]_left_touch_sensor_fr_joint" type="fixed">
    <parent link="left_foot [foot]"/>
    <child link="left_touch_sensor_fr"/>
    <origin xyz="-0.041001 -0.154153 -0.061058" rpy="0 0 0"/>
  </joint>
  <link name="left_touch_sensor_fl">
    <visual>
      <origin xyz="0 0 0.0056" rpy="3.110796 0 0"/>
      <geometry>
        <cylinder radius="0.009" length="0.001"/>
      </geometry>
    </visual>
    <collision>
      <origin xyz="0 0 0.0056" rpy="3.110796 0 0"/>
      <geometry>
        <cylinder radius="0.009" length="0.001"/>
      </geometry>
    </collision>
    <visual>
      <origin xyz="0 0.000015 0.0061" rpy="3.110796 0 0"/>
      <geometry>
        <sphere radius="0.009"/>
      </geometry>
    </visual>
    <collision>
      <origin xyz="0 0.000015 0.0061" rpy="3.110796 0 0"/>
      <geometry>
        <sphere radius="0.009"/>
      </geometry>
    </collision>
    <visual>
      <origin xyz="0 -0.000015 0.0051" rpy="3.110796 0 0"/>
      <geometry>
        <sphere radius="0.009"/>
      </geometry>
    </visual>
    <collision>
      <origin xyz="0 -0.000015 0.0051" rpy="3.110796 0 0"/>
      <geometry>
        <sphere radius="0.009"/>
      </geometry>
    </collision>
  </link>
  <joint name="left_foot [foot]_left_touch_sensor_fl_joint" type="fixed">
    <parent link="left_foot [foot]"/>
    <child link="left_touch_sensor_fl"/>
    <origin xyz="0.056999 -0.154145 -0.061056" rpy="0 0 0"/>
  </joint>
  <link name="left_touch_sensor_bl">
    <visual>
      <origin xyz="0 0 0.0056" rpy="3.110796 0 0"/>
      <geometry>
        <cylinder radius="0.009" length="0.001"/>
      </geometry>
    </visual>
    <collision>
      <origin xyz="0 0 0.0056" rpy="3.110796 0 0"/>
      <geometry>
        <cylinder radius="0.009" length="0.001"/>
      </geometry>
    </collision>
    <visual>
      <origin xyz="0 0.000015 0.0061" rpy="3.110796 0 0"/>
      <geometry>
        <sphere radius="0.009"/>
      </geometry>
    </visual>
    <collision>
      <origin xyz="0 0.000015 0.0061" rpy="3.110796 0 0"/>
      <geometry>
        <sphere radius="0.009"/>
      </geometry>
    </collision>
    <visual>
      <origin xyz="0 -0.000015 0.0051" rpy="3.110796 0 0"/>
      <geometry>
        <sphere radius="0.009"/>
      </geometry>
    </visual>
    <collision>
      <origin xyz="0 -0.000015 0.0051" rpy="3.110796 0 0"/>
      <geometry>
        <sphere radius="0.009"/>
      </geometry>
    </collision>
  </link>
  <joint name="left_foot [foot]_left_touch_sensor_bl_joint" type="fixed">
    <parent link="left_foot [foot]"/>
    <child link="left_touch_sensor_bl"/>
    <origin xyz="0.057001 0.025012 -0.06106" rpy="0 0 0"/>
  </joint>
  <link name="left_touch_sensor_br">
    <visual>
      <origin xyz="0 0 0.0056" rpy="3.110796 0 0"/>
      <geometry>
        <cylinder radius="0.009" length="0.001"/>
      </geometry>
    </visual>
    <collision>
      <origin xyz="0 0 0.0056" rpy="3.110796 0 0"/>
      <geometry>
        <cylinder radius="0.009" length="0.001"/>
      </geometry>
    </collision>
    <visual>
      <origin xyz="0 0.000015 0.0061" rpy="3.110796 0 0"/>
      <geometry>
        <sphere radius="0.009"/>
      </geometry>
    </visual>
    <collision>
      <origin xyz="0 0.000015 0.0061" rpy="3.110796 0 0"/>
      <geometry>
        <sphere radius="0.009"/>
      </geometry>
    </collision>
    <visual>
      <origin xyz="0 -0.000015 0.0051" rpy="3.110796 0 0"/>
      <geometry>
        <sphere radius="0.009"/>
      </geometry>
    </visual>
    <collision>
      <origin xyz="0 -0.000015 0.0051" rpy="3.110796 0 0"/>
      <geometry>
        <sphere radius="0.009"/>
      </geometry>
    </collision>
  </link>
  <joint name="left_foot [foot]_left_touch_sensor_br_joint" type="fixed">
    <parent link="left_foot [foot]"/>
    <child link="left_touch_sensor_br"/>
    <origin xyz="-0.040999 0.025013 -0.061061" rpy="0 0 0"/>
  </joint>
  <link name="neck">
    <inertial>
      <origin rpy="0.0 0.0 0.0" xyz="0.0186912 -7.75177e-05 -0.0220143"/>
      <mass value="0.148233"/>
      <inertia ixx="3.89355e-05" ixy="-5.28709e-07" ixz="4.95698e-06" iyy="5.76318e-05" iyz="-2.28158e-08" izz="6.25414e-05"/>
    </inertial>
    <visual>
      <origin rpy="-7.1415e-32 2.28711e-32 -3.97109e-33" xyz="0.0035 0.0 -0.0093"/>
      <geometry>
        <mesh filename="package://wolfgang_description/urdf/connector_shoulder.stl"/>
      </geometry>
      <material name="connector_shoulder_material">
        <color rgba="0.247059 0.247059 0.247059 1.0"/>
      </material>
    </visual>
    <collision>
      <origin rpy="-7.1415e-32 2.28711e-32 -3.97109e-33" xyz="0.0035 1.6604e-34 -0.00465"/>
      <geometry>
        <box size="0.036 0.04 0.0093"/>
      </geometry>
    </collision>
    <visual>
      <origin rpy="3.14159 -1.5708 0.0" xyz="0.036 3.10152e-17 -0.024"/>
      <geometry>
        <mesh filename="package://wolfgang_description/urdf/mx-64-body.stl"/>
      </geometry>
      <material name="mx-64-body_material">
        <color rgba="0.247059 0.247059 0.247059 1.0"/>
      </material>
    </visual>
    <collision>
      <origin rpy="3.14159 -1.5708 0.0" xyz="0.01845 3.8809e-17 -0.024"/>
      <geometry>
        <box size="0.0402 0.041 0.0611"/>
      </geometry>
    </collision>
  </link>
  <link name="head">
    <inertial>
      <origin rpy="0.0 0.0 0.0" xyz="0.000411708 0.0674937 -0.0200647"/>
      <mass value="0.301358"/>
      <inertia ixx="0.000344265" ixy="-2.07263e-05" ixz="1.05826e-06" iyy="0.000333713" iyz="5.11722e-05" izz="0.000421898"/>
    </inertial>
    <visual>
      <origin rpy="-1.5708 -1.5708 0.0" xyz="0.0432 0.0795 -0.0235"/>
      <geometry>
        <mesh filename="package://wolfgang_description/urdf/lense.stl"/>
      </geometry>
      <material name="lense_material">
        <color rgba="0.647059 0.647059 0.647059 1.0"/>
      </material>
    </visual>
    <collision>
      <origin rpy="-3.33067e-16 -1.5708 0.0" xyz="0.0351 0.0795 -0.0235"/>
      <geometry>
        <cylinder length="0.0162" radius="0.0215"/>
      </geometry>
    </collision>
    <collision>
      <origin rpy="-3.33067e-16 -1.5708 0.0" xyz="0.021 0.0795 -0.0235"/>
      <geometry>
        <cylinder length="0.012" radius="0.01675"/>
      </geometry>
    </collision>
    <visual>
      <origin rpy="3.88389e-31 -1.5433e-31 1.35585e-31" xyz="0.0 0.0 3.46945e-18"/>
      <geometry>
        <mesh filename="package://wolfgang_description/urdf/sea_ninjaflex.stl"/>
      </geometry>
      <material name="sea_ninjaflex_material">
        <color rgba="0.647059 0.647059 0.647059 1.0"/>
      </material>
    </visual>
    <collision>
      <origin rpy="3.88389e-31 -1.5433e-31 1.35585e-31" xyz="-2.02057e-34 1.07341e-34 0.0045"/>
      <geometry>
        <cylinder length="0.009" radius="0.025"/>
      </geometry>
    </collision>
    <visual>
      <origin rpy="-8.16317e-16 -2.22045e-16 3.14159" xyz="-2.08167e-17 -5.55112e-17 0.009"/>
      <geometry>
        <mesh filename="package://wolfgang_description/urdf/sea_connector.stl"/>
      </geometry>
      <material name="sea_connector_material">
        <color rgba="0.647059 0.647059 0.647059 1.0"/>
      </material>
    </visual>
    <collision>
      <origin rpy="-8.16317e-16 -2.22045e-16 3.14159" xyz="-1.95677e-17 -5.41482e-17 0.0115"/>
      <geometry>
        <cylinder length="0.005" radius="0.025"/>
      </geometry>
    </collision>
    <visual>
      <origin rpy="-1.74915e-15 -1.11022e-15 -1.38778e-15" xyz="0.01 0.065 0.024"/>
      <geometry>
        <mesh filename="package://wolfgang_description/urdf/camera_side_basler_wolfgang_v2.2_right.stl"/>
      </geometry>
      <material name="camera_side_basler_wolfgang_v2.2_right_material">
        <color rgba="0.647059 0.647059 0.647059 1.0"/>
      </material>
    </visual>
    <collision>
      <origin rpy="-1.74915e-15 -1.11022e-15 -1.38778e-15" xyz="0.0007814 0.0775 0.00255051"/>
      <geometry>
        <box size="0.127 0.055 0.00710102"/>
      </geometry>
    </collision>
    <visual>
      <origin rpy="-1.14124e-18 -9.99201e-16 -7.21645e-16" xyz="0.01 0.065 -0.051"/>
      <geometry>
        <mesh filename="package://wolfgang_description/urdf/camera_side_basler_wolfgang_v2.2_left.stl"/>
      </geometry>
      <material name="camera_side_basler_wolfgang_v2.2_left_material">
        <color rgba="0.647059 0.647059 0.647059 1.0"/>
      </material>
    </visual>
    <collision>
      <origin rpy="-1.14124e-18 -9.99201e-16 -7.21645e-16" xyz="0.0007814 0.0775 -0.0495505"/>
      <geometry>
        <box size="0.127 0.055 0.00710102"/>
      </geometry>
    </collision>
    <visual>
      <origin rpy="-1.5708 -1.5708 0.0" xyz="0.015 0.0795 -0.0235"/>
      <geometry>
        <mesh filename="package://wolfgang_description/urdf/basler_ace_gige_c-mount_v01.stl"/>
      </geometry>
      <material name="basler_ace_gige_c-mount_v01_material">
        <color rgba="0.647059 0.647059 0.647059 1.0"/>
      </material>
    </visual>
    <collision>
      <origin rpy="-1.5708 -1.5708 0.0" xyz="-0.018 0.0795 -0.0235"/>
      <geometry>
        <box size="0.029 0.042 0.029"/>
      </geometry>
    </collision>
    <collision>
      <origin rpy="1.05471e-15 -1.5708 0.0" xyz="0.009 0.0795 -0.0235"/>
      <geometry>
        <cylinder length="0.012" radius="0.014"/>
      </geometry>
    </collision>
    <visual>
      <origin rpy="3.33067e-16 -1.5708 0.0" xyz="0.003 0.065 -0.037945"/>
      <geometry>
        <mesh filename="package://wolfgang_description/urdf/camera_lower_basler_wolfgang_imu_v2.2.stl"/>
      </geometry>
      <material name="camera_lower_basler_wolfgang_imu_v2.2_material">
        <color rgba="0.647059 0.647059 0.647059 1.0"/>
      </material>
    </visual>
    <collision>
      <origin rpy="3.33067e-16 -1.5708 0.0" xyz="1.9082e-17 0.029 -0.0505"/>
      <geometry>
        <box size="0.006 0.072 0.03"/>
      </geometry>
    </collision>
    <collision>
      <origin rpy="3.33067e-16 -1.5708 0.0" xyz="-4.77049e-17 0.029 0.0165"/>
      <geometry>
        <box size="0.006 0.072 0.03"/>
      </geometry>
    </collision>
    <collision>
      <origin rpy="3.33067e-16 -1.5708 0.0" xyz="1.82146e-17 0.0615 -0.017"/>
      <geometry>
        <box size="0.073 0.007 0.03"/>
      </geometry>
    </collision>
    <collision>
      <origin rpy="3.33067e-16 -1.5708 0.0" xyz="-0.0125 0.069 -0.0235"/>
      <geometry>
        <box size="0.045 0.022 0.055"/>
      </geometry>
    </collision>
  </link>
  <link name="camera">
    <inertial>
      <origin rpy="0.0 0.0 0.0" xyz="0.0 0.0 0.0"/>
      <mass value="1e-09"/>
      <inertia ixx="0.0" ixy="0.0" ixz="0.0" iyy="0.0" iyz="0.0" izz="0.0"/>
    </inertial>
  </link>
  <joint name="camera_frame" type="fixed">
    <origin rpy="-1.5708 -1.45465e-14 -3.33067e-16" xyz="0.0437 0.0795 -0.0235"/>
    <axis xyz="0.0 0.0 0.0"/>
    <parent link="head"/>
    <child link="camera"/>
  </joint>
  <!--
  Removed due to extrinsic calibration
  <link name="camera_optical_frame">
    <inertial>
      <origin rpy="0.0 0.0 0.0" xyz="0.0 0.0 0.0"/>
      <mass value="1e-09"/>
      <inertia ixx="0.0" ixy="0.0" ixz="0.0" iyy="0.0" iyz="0.0" izz="0.0"/>
    </inertial>
  </link>
  <joint name="camera_optical_frame_frame" type="fixed">
    <origin rpy="3.14159 -1.5708 0.0" xyz="0.0432 0.08 -0.0235"/>
    <axis xyz="0.0 0.0 0.0"/>
    <parent link="head"/>
    <child link="camera_optical_frame"/>
  </joint>
  -->
  <link name="imu_frame_2">
    <inertial>
      <origin rpy="0.0 0.0 0.0" xyz="0.0 0.0 0.0"/>
      <mass value="1e-09"/>
      <inertia ixx="0.0" ixy="0.0" ixz="0.0" iyy="0.0" iyz="0.0" izz="0.0"/>
    </inertial>
  </link>
  <joint name="imu_frame_2_frame" type="fixed">
    <origin rpy="-1.5708 -3.88578e-16 3.33067e-16" xyz="-0.02545 0.0535 -0.0235"/>
    <axis xyz="0.0 0.0 0.0"/>
    <parent link="head"/>
    <child link="imu_frame_2"/>
  </joint>
  <joint name="HeadTilt" type="revolute">
    <origin rpy="-1.5708 3.17216e-15 -5.33479e-15" xyz="0.036 0.0235 -0.024"/>
    <axis xyz="-0.0 -0.0 1.0"/>
    <parent link="neck"/>
    <child link="head"/>
    <limit effort="7.3" lower="-1.5708" upper="1.0472" velocity="8.17"/>
    <dynamics damping="0.65" friction="1.73"/>
  </joint>
  <joint name="HeadPan" type="revolute">
    <origin rpy="-3.14159 3.41087e-16 -4.44089e-16" xyz="-0.0095 2.82644e-16 0.2345"/>
    <axis xyz="-0.0 -0.0 -1.0"/>
    <parent link="torso"/>
    <child link="neck"/>
    <limit effort="7.3" lower="-2.35619" upper="2.35619" velocity="8.17"/>
    <dynamics damping="0.65" friction="1.73"/>
  </joint>
  <joint name="LHipPitch" type="revolute">
    <origin rpy="2.67116e-16 -1.5708 0.0" xyz="0.026 6.93889e-18 -0.0691"/>
    <axis xyz="7.95491e-17 -3.00167e-16 -1.0"/>
    <parent link="l_hip_2"/>
    <child link="l_upper_leg"/>
    <limit effort="10" lower="-1.91986" upper="2.0944" velocity="5.76"/>
    <dynamics damping="1.23" friction="2.55"/>
  </joint>
  <joint name="LHipRoll" type="revolute">
    <origin rpy="3.14159 1.5708 0.0" xyz="-0.046 0.0414 6.93889e-18"/>
    <axis xyz="-0.0 -0.0 -1.0"/>
    <parent link="l_hip_1"/>
    <child link="l_hip_2"/>
    <limit effort="10" lower="-1.5708" upper="1.5708" velocity="5.76"/>
    <dynamics damping="1.23" friction="2.55"/>
  </joint>
  <joint name="LHipYaw" type="revolute">
    <origin rpy="-1.5708 -0.0 0.0" xyz="1.82493e-15 0.055 -4.22839e-18"/>
    <axis xyz="-0.0 1.0 -0.0"/>
    <parent link="torso"/>
    <child link="l_hip_1"/>
    <limit effort="10" lower="-1.5708" upper="1.5708" velocity="5.76"/>
    <dynamics damping="1.23" friction="2.55"/>
  </joint>
  <joint name="RHipPitch" type="revolute">
    <origin rpy="-1.5708 1.5708 0.0" xyz="-0.0265 -9.71445e-17 -0.0691"/>
    <axis xyz="-0.0 1.0 -0.0"/>
    <parent link="r_hip_2"/>
    <child link="r_upper_leg"/>
    <limit effort="10" lower="-2.0944" upper="1.91986" velocity="5.76"/>
    <dynamics damping="1.23" friction="2.55"/>
  </joint>
  <joint name="RHipRoll" type="revolute">
    <origin rpy="-3.14159 1.5708 0.0" xyz="-0.046 0.0414 6.93889e-18"/>
    <axis xyz="-0.0 -0.0 -1.0"/>
    <parent link="r_hip_1"/>
    <child link="r_hip_2"/>
    <limit effort="10" lower="-1.5708" upper="1.5708" velocity="5.76"/>
    <dynamics damping="1.23" friction="2.55"/>
  </joint>
  <joint name="RHipYaw" type="revolute">
    <origin rpy="-1.5708 -0.0 0.0" xyz="7.99361e-15 -0.055 4.68375e-17"/>
    <axis xyz="-0.0 1.0 -0.0"/>
    <parent link="torso"/>
    <child link="r_hip_1"/>
    <limit effort="10" lower="-1.5708" upper="1.5708" velocity="5.76"/>
    <dynamics damping="1.23" friction="2.55"/>
  </joint>



  <transmission name="HeadPanTransmission">
    <type>transmission_interface/SimpleTransmission</type>
    <joint name="HeadPan">
      <hardwareInterface>hardware_interface/EffortJointInterface</hardwareInterface>
    </joint>
    <actuator name="HeadPanMotor">
      <mechanicalReduction>1.0</mechanicalReduction>
    </actuator>
  </transmission>
  <transmission name="HeadTiltTransmission">
    <type>transmission_interface/SimpleTransmission</type>
    <joint name="HeadTilt">
      <hardwareInterface>hardware_interface/EffortJointInterface</hardwareInterface>
    </joint>
    <actuator name="HeadTiltMotor">
      <mechanicalReduction>1.0</mechanicalReduction>
    </actuator>
  </transmission>
  <transmission name="LShoulderPitchTransmission">
    <type>transmission_interface/SimpleTransmission</type>
    <joint name="LShoulderPitch">
      <hardwareInterface>hardware_interface/EffortJointInterface</hardwareInterface>
    </joint>
    <actuator name="LShoulderPitchMotor">
      <mechanicalReduction>1.0</mechanicalReduction>
    </actuator>
  </transmission>
  <transmission name="LShoulderRollTransmission">
    <type>transmission_interface/SimpleTransmission</type>
    <joint name="LShoulderRoll">
      <hardwareInterface>hardware_interface/EffortJointInterface</hardwareInterface>
    </joint>
    <actuator name="LShoulderRollTransmission">
      <mechanicalReduction>1.0</mechanicalReduction>
    </actuator>
  </transmission>
  <transmission name="LElbowTransmission">
    <type>transmission_interface/SimpleTransmission</type>
    <joint name="LElbow">
      <hardwareInterface>hardware_interface/EffortJointInterface</hardwareInterface>
    </joint>
    <actuator name="LElbowMotor">
      <mechanicalReduction>1.0</mechanicalReduction>
    </actuator>
  </transmission>
  <transmission name="RShoulderPitchTransmission">
    <type>transmission_interface/SimpleTransmission</type>
    <joint name="RShoulderPitch">
      <hardwareInterface>hardware_interface/EffortJointInterface</hardwareInterface>
    </joint>
    <actuator name="RShoulderPitchMotor">
      <mechanicalReduction>1.0</mechanicalReduction>
    </actuator>
  </transmission>
  <transmission name="RShoulderRollTransmission">
    <type>transmission_interface/SimpleTransmission</type>
    <joint name="RShoulderRoll">
      <hardwareInterface>hardware_interface/EffortJointInterface</hardwareInterface>
    </joint>
    <actuator name="RShoulderRollMotor">
      <mechanicalReduction>1.0</mechanicalReduction>
    </actuator>
  </transmission>
  <transmission name="RElbowTransmission">
    <type>transmission_interface/SimpleTransmission</type>
    <joint name="RElbow">
      <hardwareInterface>hardware_interface/EffortJointInterface</hardwareInterface>
    </joint>
    <actuator name="RElbowMotor">
      <mechanicalReduction>1.0</mechanicalReduction>
    </actuator>
  </transmission>
  <transmission name="LHipYawTransmission">
    <type>transmission_interface/SimpleTransmission</type>
    <joint name="LHipYaw">
      <hardwareInterface>hardware_interface/EffortJointInterface</hardwareInterface>
    </joint>
    <actuator name="LHipYawMotor">
      <mechanicalReduction>1.0</mechanicalReduction>
    </actuator>
  </transmission>
  <transmission name="LHipRollTransmission">
    <type>transmission_interface/SimpleTransmission</type>
    <joint name="LHipRoll">
      <hardwareInterface>hardware_interface/EffortJointInterface</hardwareInterface>
    </joint>
    <actuator name="LHipRollMotor">
      <mechanicalReduction>1.0</mechanicalReduction>
    </actuator>
  </transmission>
  <transmission name="LHipPitchTransmission">
    <type>transmission_interface/SimpleTransmission</type>
    <joint name="LHipPitch">
      <hardwareInterface>hardware_interface/EffortJointInterface</hardwareInterface>
    </joint>
    <actuator name="LHipPitchMotor">
      <mechanicalReduction>1.0</mechanicalReduction>
    </actuator>
  </transmission>
  <transmission name="LKneeTransmission">
    <type>transmission_interface/SimpleTransmission</type>
    <joint name="LKnee">
      <hardwareInterface>hardware_interface/EffortJointInterface</hardwareInterface>
    </joint>
    <actuator name="LKneeMotor">
      <mechanicalReduction>1.0</mechanicalReduction>
    </actuator>
  </transmission>
  <transmission name="LAnklePitchTransmission">
    <type>transmission_interface/SimpleTransmission</type>
    <joint name="LAnklePitch">
      <hardwareInterface>hardware_interface/EffortJointInterface</hardwareInterface>
    </joint>
    <actuator name="LAnklePitchMotor">
      <mechanicalReduction>1.0</mechanicalReduction>
    </actuator>
  </transmission>
  <transmission name="LAnkleRollTransmission">
    <type>transmission_interface/SimpleTransmission</type>
    <joint name="LAnkleRoll">
      <hardwareInterface>hardware_interface/EffortJointInterface</hardwareInterface>
    </joint>
    <actuator name="LAnkleRollMotor">
      <mechanicalReduction>1.0</mechanicalReduction>
    </actuator>
  </transmission>
  <transmission name="RHipYawTransmission">
    <type>transmission_interface/SimpleTransmission</type>
    <joint name="RHipYaw">
      <hardwareInterface>hardware_interface/EffortJointInterface</hardwareInterface>
    </joint>
    <actuator name="RHipYawMotor">
      <mechanicalReduction>1.0</mechanicalReduction>
    </actuator>
  </transmission>
  <transmission name="RHipRollTransmission">
    <type>transmission_interface/SimpleTransmission</type>
    <joint name="RHipRoll">
      <hardwareInterface>hardware_interface/EffortJointInterface</hardwareInterface>
    </joint>
    <actuator name="RHipRollMotor">
      <mechanicalReduction>1.0</mechanicalReduction>
    </actuator>
  </transmission>
  <transmission name="RHipPitchTransmission">
    <type>transmission_interface/SimpleTransmission</type>
    <joint name="RHipPitch">
      <hardwareInterface>hardware_interface/EffortJointInterface</hardwareInterface>
    </joint>
    <actuator name="RHipPitchMotor">
      <mechanicalReduction>1.0</mechanicalReduction>
    </actuator>
  </transmission>
  <transmission name="RKneeTransmission">
    <type>transmission_interface/SimpleTransmission</type>
    <joint name="RKnee">
      <hardwareInterface>hardware_interface/EffortJointInterface</hardwareInterface>
    </joint>
    <actuator name="RKneeMotor">
      <mechanicalReduction>1.0</mechanicalReduction>
    </actuator>
  </transmission>
  <transmission name="RAnklePitchTransmission">
    <type>transmission_interface/SimpleTransmission</type>
    <joint name="RAnklePitch">
      <hardwareInterface>hardware_interface/EffortJointInterface</hardwareInterface>
    </joint>
    <actuator name="RAnklePitchMotor">
      <mechanicalReduction>1.0</mechanicalReduction>
    </actuator>
  </transmission>
  <transmission name="RAnkleRollTransmission">
    <type>transmission_interface/SimpleTransmission</type>
    <joint name="RAnkleRoll">
      <hardwareInterface>hardware_interface/EffortJointInterface</hardwareInterface>
    </joint>
    <actuator name="RAnkleRollMotor">
      <mechanicalReduction>1.0</mechanicalReduction>
    </actuator>
  </transmission>
  <gazebo reference="r_foot">
    <material>Gazebo/FlatBlack</material>
    <kp>1000000.0</kp>
    <kd>100.0</kd>
    <mu1>1.0</mu1>
    <mu2>1.0</mu2>
    <fdir1>1 0 0</fdir1>
    <maxVel>1.0</maxVel>
    <minDepth>0.00</minDepth>
  </gazebo>
  <gazebo reference="l_foot">
    <material>Gazebo/FlatBlack</material>
    <kp>1000000.0</kp>
    <kd>100.0</kd>
    <mu1>1.0</mu1>
    <mu2>1.0</mu2>
    <fdir1>1 0 0</fdir1>
    <maxVel>1.0</maxVel>
    <minDepth>0.00</minDepth>
  </gazebo>
  <gazebo>
    <plugin filename="libgazebo_ros_control.so" name="gazebo_ros_control">
      <robotNamespace>$(arg sim_ns)</robotNamespace>
    </plugin>
  </gazebo>
  <gazebo reference="camera_optical_frame">
    <sensor name="camera" type="camera">
      <pose>-0.050000 -0.010000 0.000000 -1.5708 0.000000 -3.141592</pose>
      <camera name="__default__">
        <horizontal_fov>0.57</horizontal_fov>
        <image>
          <width>620</width>
          <height>480</height>
        </image>
        <clip>
          <near>0.001000</near>
          <far>100.000000</far>
        </clip>
      </camera>
      <always_on>1</always_on>
      <update_rate>30.000000</update_rate>
      <visualize>1</visualize>
      <plugin filename="libgazebo_ros_camera.so" name="camera_controller">
        <alwaysOn>true</alwaysOn>
        <updateRate>30</updateRate>
        <cameraName>camera</cameraName>
        <imageTopicName>camera/image_proc</imageTopicName>
        <cameraInfoTopicName>camera_info</cameraInfoTopicName>
        <frameName>camera_optical_frame</frameName>
        <hackBaseline>0.07</hackBaseline>
        <distortionK1>0.0</distortionK1>
        <distortionK2>0.0</distortionK2>
        <distortionK3>0.0</distortionK3>
        <distortionT1>0.0</distortionT1>
        <distortionT2>0.0</distortionT2>
      </plugin>
    </sensor>
  </gazebo>
  <gazebo reference="imu_frame">
    <gravity>true</gravity>
    <sensor name="imu_sensor" type="imu">
      <always_on>true</always_on>
      <update_rate>100</update_rate>
      <visualize>true</visualize>
      <topic>__default_topic__</topic>
      <plugin filename="libgazebo_ros_imu_sensor.so" name="imu_plugin">
        <topicName>imu</topicName>
        <bodyName>imu_frame</bodyName>
        <updateRateHZ>100.0</updateRateHZ>
        <gaussianNoise>0.0</gaussianNoise>
        <xyzOffset>0 0 0</xyzOffset>
        <rpyOffset>0 0 0</rpyOffset>
        <frameName>imu_frame</frameName>
      </plugin>
      <pose>0 0 0 0 0 0</pose>
    </sensor>
  </gazebo>
  <gazebo reference="imu_frame_2">
    <gravity>true</gravity>
    <sensor name="imu_head" type="imu">
      <always_on>true</always_on>
      <update_rate>100</update_rate>
      <visualize>true</visualize>
      <topic>__default_topic__</topic>
      <plugin filename="libgazebo_ros_imu_sensor.so" name="imu_plugin">
        <topicName>imu_head</topicName>
        <bodyName>head</bodyName>
        <updateRateHZ>100.0</updateRateHZ>
        <gaussianNoise>0.0</gaussianNoise>
        <xyzOffset>0 0 0</xyzOffset>
        <rpyOffset>0 0 0</rpyOffset>
        <frameName>head</frameName>
      </plugin>
      <pose>0 0 0 0 0 0</pose>
    </sensor>
  </gazebo>
  <gazebo>
    <plugin filename="libgazebo_ros_f3d.so" name="gazebo_ros_f3d">
      <alwaysOn>true</alwaysOn>
      <updateRate>100.0</updateRate>
      <bodyName>llb</bodyName>
      <topicName>sim_strain_gauges/llb</topicName>
      <robotNamespace>$(arg sim_ns)</robotNamespace>
    </plugin>
    <plugin filename="libgazebo_ros_f3d.so" name="gazebo_ros_f3d">
      <alwaysOn>true</alwaysOn>
      <updateRate>100.0</updateRate>
      <bodyName>llf</bodyName>
      <topicName>sim_strain_gauges/llf</topicName>
      <robotNamespace>$(arg sim_ns)</robotNamespace>
    </plugin>
    <plugin filename="libgazebo_ros_f3d.so" name="gazebo_ros_f3d">
      <alwaysOn>true</alwaysOn>
      <updateRate>100.0</updateRate>
      <bodyName>lrf</bodyName>
      <topicName>sim_strain_gauges/lrf</topicName>
      <robotNamespace>$(arg sim_ns)</robotNamespace>
    </plugin>
    <plugin filename="libgazebo_ros_f3d.so" name="gazebo_ros_f3d">
      <alwaysOn>true</alwaysOn>
      <updateRate>100.0</updateRate>
      <bodyName>lrb</bodyName>
      <topicName>sim_strain_gauges/lrb</topicName>
      <robotNamespace>$(arg sim_ns)</robotNamespace>
    </plugin>
    <plugin filename="libgazebo_ros_f3d.so" name="gazebo_ros_f3d">
      <alwaysOn>true</alwaysOn>
      <updateRate>100.0</updateRate>
      <bodyName>rlb</bodyName>
      <topicName>sim_strain_gauges/rlb</topicName>
      <robotNamespace>$(arg sim_ns)</robotNamespace>
    </plugin>
    <plugin filename="libgazebo_ros_f3d.so" name="gazebo_ros_f3d">
      <alwaysOn>true</alwaysOn>
      <updateRate>100.0</updateRate>
      <bodyName>rlf</bodyName>
      <topicName>sim_strain_gauges/rlf</topicName>
      <robotNamespace>$(arg sim_ns)</robotNamespace>
    </plugin>
    <plugin filename="libgazebo_ros_f3d.so" name="gazebo_ros_f3d">
      <alwaysOn>true</alwaysOn>
      <updateRate>100.0</updateRate>
      <bodyName>rrf</bodyName>
      <topicName>sim_strain_gauges/rrf</topicName>
      <robotNamespace>$(arg sim_ns)</robotNamespace>
    </plugin>
    <plugin filename="libgazebo_ros_f3d.so" name="gazebo_ros_f3d">
      <alwaysOn>true</alwaysOn>
      <updateRate>100.0</updateRate>
      <bodyName>rrb</bodyName>
      <topicName>sim_strain_gauges/rrb</topicName>
      <robotNamespace>$(arg sim_ns)</robotNamespace>
    </plugin>
  </gazebo>
</robot>
