#VRML_SIM R2020b utf8
# license: Apache License 2.0
# license url: http://www.apache.org/licenses/LICENSE-2.0
# This is a proto file for Webots for the Wolfgang
# Extracted from: wolfgang.urdf

PROTO Wolfgang [
  field  SFVec3f     translation     0 0 0
  field  SFRotation  rotation        0 1 0 0
  field  SFString    name            "Wolfgang"  # Is `Robot.name`.
  field  SFString    controller      "void"      # Is `Robot.controller`.
  field  MFString    controllerArgs  []          # Is `Robot.controllerArgs`.
  field  SFString    customData      ""          # Is `Robot.customData`.
  field  SFBool      supervisor      FALSE       # Is `Robot.supervisor`.
  field  SFBool      synchronization TRUE        # Is `Robot.synchronization`.
  field  SFBool      selfCollision   FALSE       # Is `Robot.selfCollision`.
]
{
  Robot {
    translation IS translation
    rotation IS rotation
    controller IS controller
    controllerArgs IS controllerArgs
    customData IS customData
    supervisor IS supervisor
    synchronization IS synchronization
    selfCollision IS selfCollision
    children [
      Wolfgang_torsoMesh {
      }
      Solid {
        translation -0.036975 -0.047461 0.224000
        rotation 0.000000 1.000000 0.000000 0.000000
        children [
          Accelerometer {
            name "imu accelerometer"
          }
          Gyro {
            name "imu gyro"
          }
          Compass {
            name "imu compass"
          }
        ]
        name "imu_frame"
      }
      HingeJoint {
        jointParameters HingeJointParameters {
          axis 0.000003 -1.000000 -0.000000
          anchor -0.001500 -0.076500 0.203500
          dampingConstant 0.53
          staticFriction 0.0
        }
        device [
          RotationalMotor {
            name "RShoulderPitch"
            maxVelocity 10.33
            minPosition -3.14159
            maxPosition 3.14159
            maxTorque 5.43
          }
          PositionSensor {
            name "RShoulderPitch_sensor"
          }
        ]
        endPoint Solid {
          translation -0.001500 -0.076500 0.203500
          rotation 0.000000 0.000000 -1.000000 3.141590
          children [
            Wolfgang_r_shoulderMesh {
            }
            HingeJoint {
              jointParameters HingeJointParameters {
                axis 1.000000 -0.000004 0.000004
                anchor -0.016950 0.042000 0.000000
                dampingConstant 0.53
                staticFriction 0.0
              }
              device [
                RotationalMotor {
                  name "RShoulderRoll"
                  maxVelocity 10.33
                  maxPosition 3.14159
                  maxTorque 5.43
                }
                PositionSensor {
                  name "RShoulderRoll_sensor"
                }
              ]
              endPoint Solid {
                translation -0.016950 0.042000 0.000000
                rotation 0.577350 -0.577352 -0.577350 2.094399
                children [
                  Wolfgang_r_upper_armMesh {
                  }
                  HingeJoint {
                    jointParameters HingeJointParameters {
                      axis 1.000000 -0.000004 -0.000004
                      anchor 0.024000 -0.144000 -0.023500
                      dampingConstant 0.53
                      staticFriction 0.0
                    }
                    device [
                      RotationalMotor {
                        name "RElbow"
                        maxVelocity 10.33
                        minPosition -1.0472
                        maxPosition 1.5708
                        maxTorque 5.43
                      }
                      PositionSensor {
                        name "RElbow_sensor"
                      }
                    ]
                    endPoint Solid {
                      translation 0.024000 -0.144000 -0.023500
                      rotation -0.577350 0.577352 -0.577350 2.094399
                      children [
                        Wolfgang_r_lower_armMesh {
                        }
                        Solid {
                          translation 0.000000 -0.226182 -0.023500
                          rotation 0.577350 -0.577352 -0.577350 2.094399
                          name "r_wrist"
                        }
                      ]
                      name "r_lower_arm"
                      boundingObject Transform {
                        translation 0.000000 -0.106327 -0.022450
                        rotation 0.000000 1.000000 0.000000 0.000000
                        children [
                          Box {
                            size 0.078999 0.238653 0.046100
                          }
                        ]
                      }
                      physics Physics {
                        density -1
                        mass 0.207774
                        centerOfMass [ 0.000436 -0.060513 -0.023555 ]
                        inertiaMatrix [
                          1.088000e-03 8.903240e-05 1.100760e-03
                          -1.161880e-06 -5.015150e-09 -3.226660e-08
                        ]
                      }
                    }
                  }
                ]
                name "r_upper_arm"
                boundingObject Transform {
                  translation 0.000000 -0.075500 -0.022450
                  rotation 0.000000 1.000000 0.000000 0.000000
                  children [
                    Box {
                      size 0.052500 0.177000 0.046100
                    }
                  ]
                }
                physics Physics {
                  density -1
                  mass 0.228498
                  centerOfMass [ 0.000098 -0.032582 -0.023923 ]
                  inertiaMatrix [
                    2.414550e-04 1.794910e-04 3.711270e-04
                    8.094790e-07 7.570950e-08 -2.798500e-06
                  ]
                }
              }
            }
          ]
          name "r_shoulder"
          boundingObject Transform {
            translation 0.000000 0.033500 0.000000
            rotation 0.000000 1.000000 0.000000 0.000000
            children [
              Box {
                size 0.063900 0.067000 0.050000
              }
            ]
          }
          physics Physics {
            density -1
            mass 0.041445
            centerOfMass [ -0.013540 0.028402 -0.000002 ]
            inertiaMatrix [
              1.854730e-05 2.766490e-05 3.495730e-05
              7.630580e-06 -9.413860e-10 8.718250e-10
            ]
          }
        }
      }
      HingeJoint {
        jointParameters HingeJointParameters {
          axis 0.000003 1.000000 -0.000003
          anchor -0.001500 0.076500 0.203500
          dampingConstant 0.53
          staticFriction 0.0
        }
        device [
          RotationalMotor {
            name "LShoulderPitch"
            maxVelocity 10.33
            minPosition -3.14159
            maxPosition 3.14159
            maxTorque 5.43
          }
          PositionSensor {
            name "LShoulderPitch_sensor"
          }
        ]
        endPoint Solid {
          translation -0.001500 0.076500 0.203500
          rotation -0.000001 -1.000000 0.000001 3.141593
          children [
            Wolfgang_l_shoulderMesh {
            }
            HingeJoint {
              jointParameters HingeJointParameters {
                axis 1.000000 0.000004 0.000004
                anchor -0.016950 0.042000 -0.000000
                dampingConstant 0.53
                staticFriction 0.0
              }
              device [
                RotationalMotor {
                  name "LShoulderRoll"
                  maxVelocity 10.33
                  minPosition -3.14159
                  maxTorque 5.43
                }
                PositionSensor {
                  name "LShoulderRoll_sensor"
                }
              ]
              endPoint Solid {
                translation -0.016950 0.042000 -0.000000
                rotation -0.577350 -0.577352 0.577350 2.094399
                children [
                  Wolfgang_l_upper_armMesh {
                  }
                  HingeJoint {
                    jointParameters HingeJointParameters {
                      axis -1.000000 -0.000004 -0.000004
                      anchor -0.024000 -0.144000 -0.023500
                      dampingConstant 0.53
                      staticFriction 0.0
                    }
                    device [
                      RotationalMotor {
                        name "LElbow"
                        maxVelocity 10.33
                        minPosition -1.5708
                        maxPosition 1.0472
                        maxTorque 5.43
                      }
                      PositionSensor {
                        name "LElbow_sensor"
                      }
                    ]
                    endPoint Solid {
                      translation -0.024000 -0.144000 -0.023500
                      rotation -0.577350 -0.577352 0.577350 2.094399
                      children [
                        Wolfgang_l_lower_armMesh {
                        }
                        Solid {
                          translation -0.000000 -0.225182 -0.023500
                          rotation -0.577350 0.577352 -0.577350 2.094399
                          name "l_wrist"
                        }
                      ]
                      name "l_lower_arm"
                      boundingObject Transform {
                        translation -0.000000 -0.106327 -0.022450
                        rotation 0.000000 1.000000 0.000000 0.000000
                        children [
                          Box {
                            size 0.078999 0.238653 0.046100
                          }
                        ]
                      }
                      physics Physics {
                        density -1
                        mass 0.207774
                        centerOfMass [ -0.000436 -0.060513 -0.023555 ]
                        inertiaMatrix [
                          1.088000e-03 8.903240e-05 1.100760e-03
                          -1.148360e-05 5.011780e-09 -3.226660e-08
                        ]
                      }
                    }
                  }
                ]
                name "l_upper_arm"
                boundingObject Transform {
                  translation 0.000000 -0.075500 -0.022450
                  rotation 0.000000 1.000000 0.000000 0.000000
                  children [
                    Box {
                      size 0.052500 0.177000 0.046100
                    }
                  ]
                }
                physics Physics {
                  density -1
                  mass 0.228498
                  centerOfMass [ 0.000098 -0.032582 -0.023923 ]
                  inertiaMatrix [
                    2.414550e-04 1.794910e-04 3.711270e-04
                    8.094790e-07 7.570950e-08 -2.798500e-06
                  ]
                }
              }
            }
          ]
          name "l_shoulder"
          boundingObject Transform {
            translation 0.000000 0.033500 0.000000
            rotation 0.000000 1.000000 0.000000 0.000000
            children [
              Box {
                size 0.063900 0.067000 0.050000
              }
            ]
          }
          physics Physics {
            density -1
            mass 0.041445
            centerOfMass [ -0.013540 0.028402 0.000002 ]
            inertiaMatrix [
              1.854730e-05 2.766490e-05 3.495730e-05
              7.630580e-06 9.413860e-10 -8.718250e-10
            ]
          }
        }
      }
      HingeJoint {
        jointParameters HingeJointParameters {
          axis 0.000000 -0.000004 -1.000000
          anchor 0.000000 -0.055000 0.000000
          dampingConstant 0.92
          staticFriction 0.0
        }
        device [
          RotationalMotor {
            name "RHipYaw"
            maxVelocity 8.22
            minPosition -1.5708
            maxPosition 1.5708
            maxTorque 7.57
          }
          PositionSensor {
            name "RHipYaw_sensor"
          }
        ]
        endPoint Solid {
          translation 0.000000 -0.055000 0.000000
          rotation -1.000000 -0.000000 0.000000 1.570800
          children [
            Wolfgang_r_hip_1Mesh {
            }
            HingeJoint {
              jointParameters HingeJointParameters {
                axis 1.000000 -0.000003 -0.000004
                anchor -0.046000 0.041400 0.000000
                dampingConstant 0.92
                staticFriction 0.0
              }
              device [
                RotationalMotor {
                  name "RHipRoll"
                  maxVelocity 8.22
                  minPosition -1.5708
                  maxPosition 1.5708
                  maxTorque 7.57
                }
                PositionSensor {
                  name "RHipRoll_sensor"
                }
              ]
              endPoint Solid {
                translation -0.046000 0.041400 0.000000
                rotation -0.707105 0.000001 0.707108 3.141591
                children [
                  Wolfgang_r_hip_2Mesh {
                  }
                  HingeJoint {
                    jointParameters HingeJointParameters {
                      axis -1.000000 -0.000004 0.000004
                      anchor -0.026500 -0.000000 -0.069100
                      dampingConstant 0.92
                      staticFriction 0.0
                    }
                    device [
                      RotationalMotor {
                        name "RHipPitch"
                        maxVelocity 8.22
                        minPosition -1.5708
                        maxPosition 0.785398
                        maxTorque 7.57
                      }
                      PositionSensor {
                        name "RHipPitch_sensor"
                      }
                    ]
                    endPoint Solid {
                      translation -0.026500 -0.000000 -0.069100
                      rotation -0.577350 0.577350 0.577352 2.094399
                      children [
                        Wolfgang_r_upper_legMesh {
                        }
                        HingeJoint {
                          jointParameters HingeJointParameters {
                            axis -0.000000 -1.000000 -0.000000
                            anchor -0.003923 -0.051000 -0.169043
                            dampingConstant 1.0
                            staticFriction 0.0
                          }
                          device [
                            RotationalMotor {
                              name "RKnee"
                              maxVelocity 10.0
                              minPosition -2.96706
                              maxTorque 10.0
                            }
                            PositionSensor {
                              name "RKnee_sensor"
                            }
                          ]
                          endPoint Solid {
                            translation -0.003923 -0.051000 -0.169043
                            rotation 0.000000 -1.000000 -0.000000 0.261799
                            children [
                              Wolfgang_r_lower_legMesh {
                              }
                              HingeJoint {
                                jointParameters HingeJointParameters {
                                  axis 0.000000 -1.000000 0.000004
                                  anchor -0.000000 0.050500 -0.170000
                                  dampingConstant 0.92
                                  staticFriction 0.0
                                }
                                device [
                                  RotationalMotor {
                                    name "RAnklePitch"
                                    maxVelocity 8.22
                                    minPosition -1.5708
                                    maxPosition 1.22173
                                    maxTorque 7.57
                                  }
                                  PositionSensor {
                                    name "RAnklePitch_sensor"
                                  }
                                ]
                                endPoint Solid {
                                  translation -0.000000 0.050500 -0.170000
                                  rotation -0.999668 0.018230 0.018230 1.571132
                                  children [
                                    Wolfgang_r_ankleMesh {
                                    }
                                    HingeJoint {
                                      jointParameters HingeJointParameters {
                                        axis -1.000000 0.000004 -0.000000
                                        anchor -0.069100 -0.000000 -0.026000
                                        dampingConstant 0.92
                                        staticFriction 0.0
                                      }
                                      device [
                                        RotationalMotor {
                                          name "RAnkleRoll"
                                          maxVelocity 8.22
                                          minPosition -1.0472
                                          maxPosition 1.0472
                                          maxTorque 7.57
                                        }
                                        PositionSensor {
                                          name "RAnkleRoll_sensor"
                                        }
                                      ]
                                      endPoint Solid {
                                        translation -0.069100 -0.000000 -0.026000
                                        rotation 0.572979 0.572976 -0.585998 2.081475
                                        children [
                                          Wolfgang_r_footMesh {
                                          }
                                          Solid {
                                            translation 0.015222 0.090768 -0.052900
                                            rotation -0.000000 0.000000 1.000000 1.570800
                                            name "r_sole"
                                          }
                                          Solid {
                                            translation 0.015000 0.184500 -0.037750
                                            rotation -0.000000 0.000000 1.000000 1.570800
                                            name "r_toe"
                                          }
                                          TouchSensor {
                                            type "force-3d"
                                            translation -0.030000 -0.007000 -0.034000
                                            rotation -0.000000 0.000000 -1.000000 1.570800
                                            children [
                                              Wolfgang_rlbMesh {
                                              }
                                              Solid {
                                                translation 0.000000 -0.000500 -0.016000
                                                rotation -0.000000 0.000000 -1.000000 3.141590
                                                name "r_cleat_l_back"
                                              }
                                            ]
                                            name "rlb"
                                            boundingObject Transform {
                                              translation 0.000000 0.000000 -0.008000
                                              rotation 0.000000 1.000000 0.000000 0.000000
                                              children [
                                                Box {
                                                  size 0.012000 0.012000 0.016000
                                                }
                                              ]
                                            }
                                            physics Physics {
                                              density -1
                                              mass 0.001660
                                              centerOfMass [ 0.000000 0.000156 -0.007759 ]
                                              inertiaMatrix [
                                                4.335200e-08 4.440490e-08 3.043970e-08
                                                4.172760e-26 1.815160e-25 -1.099300e-09
                                              ]
                                            }
                                          }
                                          TouchSensor {
                                            type "force-3d"
                                            translation -0.030000 0.177000 -0.034000
                                            rotation -0.000000 0.000000 -1.000000 1.570800
                                            children [
                                              Wolfgang_rlfMesh {
                                              }
                                              Solid {
                                                translation 0.000000 -0.000500 -0.016000
                                                rotation 0.000000 -0.000000 -1.000000 3.141590
                                                name "r_cleat_l_front"
                                              }
                                            ]
                                            name "rlf"
                                            boundingObject Transform {
                                              translation 0.000000 0.000000 -0.008000
                                              rotation 0.000000 1.000000 0.000000 0.000000
                                              children [
                                                Box {
                                                  size 0.012000 0.012000 0.016000
                                                }
                                              ]
                                            }
                                            physics Physics {
                                              density -1
                                              mass 0.001660
                                              centerOfMass [ 0.000000 0.000156 -0.007759 ]
                                              inertiaMatrix [
                                                4.335200e-08 4.440490e-08 3.043970e-08
                                                1.353550e-26 -3.318830e-24 -1.099300e-09
                                              ]
                                            }
                                          }
                                          TouchSensor {
                                            type "force-3d"
                                            translation 0.060000 0.177000 -0.034000
                                            rotation -0.000000 -0.000000 -1.000000 1.570800
                                            children [
                                              Wolfgang_rrfMesh {
                                              }
                                              Solid {
                                                translation 0.000000 -0.000500 -0.016000
                                                rotation 0.000000 -0.000000 -1.000000 3.141590
                                                name "r_cleat_r_front"
                                              }
                                            ]
                                            name "rrf"
                                            boundingObject Transform {
                                              translation 0.000000 0.000000 -0.008000
                                              rotation 0.000000 1.000000 0.000000 0.000000
                                              children [
                                                Box {
                                                  size 0.012000 0.012000 0.016000
                                                }
                                              ]
                                            }
                                            physics Physics {
                                              density -1
                                              mass 0.001660
                                              centerOfMass [ 0.000000 0.000156 -0.007759 ]
                                              inertiaMatrix [
                                                4.335200e-08 4.440490e-08 3.043970e-08
                                                -3.908200e-26 -2.925130e-24 -1.099300e-09
                                              ]
                                            }
                                          }
                                          TouchSensor {
                                            type "force-3d"
                                            translation 0.060000 -0.007000 -0.034000
                                            rotation 0.000000 0.000000 -1.000000 1.570800
                                            children [
                                              Wolfgang_rrbMesh {
                                              }
                                              Solid {
                                                translation 0.000000 -0.000500 -0.016000
                                                rotation 0.000000 0.000000 1.000000 3.141590
                                                name "r_cleat_r_back"
                                              }
                                            ]
                                            name "rrb"
                                            boundingObject Transform {
                                              translation 0.000000 0.000000 -0.008000
                                              rotation 0.000000 1.000000 0.000000 0.000000
                                              children [
                                                Box {
                                                  size 0.012000 0.012000 0.016000
                                                }
                                              ]
                                            }
                                            physics Physics {
                                              density -1
                                              mass 0.001660
                                              centerOfMass [ 0.000000 0.000156 -0.007759 ]
                                              inertiaMatrix [
                                                4.335200e-08 4.440490e-08 3.043970e-08
                                                -1.232840e-27 -2.076040e-24 -1.099300e-09
                                              ]
                                            }
                                          }
                                        ]
                                        name "r_foot"
                                        boundingObject Transform {
                                          translation 0.015000 0.085750 -0.012750
                                          rotation 0.000000 1.000000 0.000000 0.000000
                                          children [
                                            Box {
                                              size 0.106000 0.198500 0.053500
                                            }
                                          ]
                                        }
                                        physics Physics {
                                          density -1
                                          mass 0.268240
                                          centerOfMass [ 0.011970 0.091109 -0.029858 ]
                                          inertiaMatrix [
                                            8.841070e-04 3.178300e-04 1.153640e-03
                                            -3.293450e-05 5.014360e-06 -1.776930e-05
                                          ]
                                        }
                                      }
                                    }
                                  ]
                                  name "r_ankle"
                                  boundingObject Transform {
                                    translation -0.023250 -0.018050 -0.026500
                                    rotation 0.000000 1.000000 0.000000 0.000000
                                    children [
                                      Box {
                                        size 0.086700 0.065100 0.048000
                                      }
                                    ]
                                  }
                                  physics Physics {
                                    density -1
                                    mass 0.319807
                                    centerOfMass [ -0.020456 -0.015528 -0.026004 ]
                                    inertiaMatrix [
                                      1.167750e-04 2.684730e-04 2.728560e-04
                                      -4.537980e-06 6.109860e-07 -7.450810e-07
                                    ]
                                  }
                                }
                              }
                            ]
                            name "r_lower_leg"
                            boundingObject Transform {
                              translation 0.000074 0.013500 -0.085000
                              rotation 0.000000 1.000000 0.000000 0.000000
                              children [
                                Box {
                                  size 0.048040 0.078000 0.206000
                                }
                              ]
                            }
                            physics Physics {
                              density -1
                              mass 0.088064
                              centerOfMass [ 0.001424 0.018357 -0.061708 ]
                              inertiaMatrix [
                                2.844560e-04 2.389080e-04 7.569320e-05
                                8.111860e-07 -8.859630e-06 2.735930e-05
                              ]
                            }
                          }
                        }
                      ]
                      name "r_upper_leg"
                      boundingObject Transform {
                        translation 0.003592 -0.037500 -0.085165
                        rotation 0.000000 1.000000 0.000000 0.000000
                        children [
                          Box {
                            size 0.068526 0.079000 0.206322
                          }
                        ]
                      }
                      physics Physics {
                        density -1
                        mass 0.242311
                        centerOfMass [ 0.004940 -0.028322 -0.133144 ]
                        inertiaMatrix [
                          5.017210e-04 4.589290e-04 1.134090e-04
                          8.335820e-06 1.677430e-05 -4.689140e-06
                        ]
                      }
                    }
                  }
                ]
                name "r_hip_2"
                boundingObject Transform {
                  translation 0.000500 -0.018050 -0.045850
                  rotation 0.000000 1.000000 0.000000 0.000000
                  children [
                    Box {
                      size 0.048000 0.065100 0.086700
                    }
                  ]
                }
                physics Physics {
                  density -1
                  mass 0.319807
                  centerOfMass [ 0.000014 -0.015528 -0.048641 ]
                  inertiaMatrix [
                    2.686270e-04 2.680490e-04 1.213310e-04
                    6.085610e-08 6.672480e-07 3.876080e-06
                  ]
                }
              }
            }
          ]
          name "r_hip_1"
          boundingObject Transform {
            translation 0.000000 0.025987 0.000000
            rotation 0.000000 1.000000 0.000000 0.000000
            children [
              Box {
                size 0.100000 0.053175 0.050000
              }
            ]
          }
          physics Physics {
            density -1
            mass 0.068973
            centerOfMass [ 0.000000 0.010315 -0.000000 ]
            inertiaMatrix [
              2.189550e-05 1.071400e-04 1.105230e-04
              -2.444750e-14 3.067930e-15 -6.566880e-11
            ]
          }
        }
      }
      HingeJoint {
        jointParameters HingeJointParameters {
          axis 0.000000 -0.000004 -1.000000
          anchor 0.000000 0.055000 -0.000000
          dampingConstant 0.92
          staticFriction 0.0
        }
        device [
          RotationalMotor {
            name "LHipYaw"
            maxVelocity 8.22
            minPosition -1.5708
            maxPosition 1.5708
            maxTorque 7.57
          }
          PositionSensor {
            name "LHipYaw_sensor"
          }
        ]
        endPoint Solid {
          translation 0.000000 0.055000 -0.000000
          rotation -1.000000 -0.000000 0.000000 1.570800
          children [
            Wolfgang_l_hip_1Mesh {
            }
            HingeJoint {
              jointParameters HingeJointParameters {
                axis 1.000000 0.000003 -0.000004
                anchor -0.046000 0.041400 0.000000
                dampingConstant 0.92
                staticFriction 0.0
              }
              device [
                RotationalMotor {
                  name "LHipRoll"
                  maxVelocity 8.22
                  minPosition -1.5708
                  maxPosition 1.5708
                  maxTorque 7.57
                }
                PositionSensor {
                  name "LHipRoll_sensor"
                }
              ]
              endPoint Solid {
                translation -0.046000 0.041400 0.000000
                rotation 0.707105 0.000001 -0.707108 3.141591
                children [
                  Wolfgang_l_hip_2Mesh {
                  }
                  HingeJoint {
                    jointParameters HingeJointParameters {
                      axis 1.000000 -0.000000 0.000004
                      anchor 0.026000 0.000000 -0.069100
                      dampingConstant 0.92
                      staticFriction 0.0
                    }
                    device [
                      RotationalMotor {
                        name "LHipPitch"
                        maxVelocity 8.22
                        minPosition -0.785398
                        maxPosition 1.5708
                        maxTorque 7.57
                      }
                      PositionSensor {
                        name "LHipPitch_sensor"
                      }
                    ]
                    endPoint Solid {
                      translation 0.026000 0.000000 -0.069100
                      rotation 0.000000 -1.000000 0.000000 1.570800
                      children [
                        Wolfgang_l_upper_legMesh {
                        }
                        HingeJoint {
                          jointParameters HingeJointParameters {
                            axis 0.000001 0.000004 1.000000
                            anchor 0.004356 -0.168793 0.049000
                            dampingConstant 1.0
                            staticFriction 0.0
                          }
                          device [
                            RotationalMotor {
                              name "LKnee"
                              maxVelocity 10.0
                              maxPosition 2.96706
                              maxTorque 10.0
                            }
                            PositionSensor {
                              name "LKnee_sensor"
                            }
                          ]
                          endPoint Solid {
                            translation 0.004356 -0.168793 0.049000
                            rotation 0.092693 0.704064 0.704061 2.956736
                            children [
                              Wolfgang_l_lower_legMesh {
                              }
                              HingeJoint {
                                jointParameters HingeJointParameters {
                                  axis 0.000003 1.000000 0.000004
                                  anchor 0.000000 -0.050500 -0.170000
                                  dampingConstant 0.92
                                  staticFriction 0.0
                                }
                                device [
                                  RotationalMotor {
                                    name "LAnklePitch"
                                    maxVelocity 8.22
                                    minPosition -1.22173
                                    maxPosition 1.5708
                                    maxTorque 7.57
                                  }
                                  PositionSensor {
                                    name "LAnklePitch_sensor"
                                  }
                                ]
                                endPoint Solid {
                                  translation 0.000000 -0.050500 -0.170000
                                  rotation -0.000001 -0.707108 0.707105 3.141591
                                  children [
                                    Wolfgang_l_ankleMesh {
                                    }
                                    HingeJoint {
                                      jointParameters HingeJointParameters {
                                        axis 1.000000 0.000004 0.000004
                                        anchor 0.069100 0.000000 -0.026000
                                        dampingConstant 0.92
                                        staticFriction 0.0
                                      }
                                      device [
                                        RotationalMotor {
                                          name "LAnkleRoll"
                                          maxVelocity 8.22
                                          minPosition -1.0472
                                          maxPosition 1.0472
                                          maxTorque 7.57
                                        }
                                        PositionSensor {
                                          name "LAnkleRoll_sensor"
                                        }
                                      ]
                                      endPoint Solid {
                                        translation 0.069100 0.000000 -0.026000
                                        rotation 0.577350 -0.577350 0.577352 2.094399
                                        children [
                                          Wolfgang_l_footMesh {
                                          }
                                          Solid {
                                            translation -0.015222 0.090768 -0.052900
                                            rotation 0.000000 -0.000000 1.000000 1.570800
                                            name "l_sole"
                                          }
                                          Solid {
                                            translation -0.015000 0.184500 -0.037750
                                            rotation 0.000000 -0.000000 1.000000 1.570800
                                            name "l_toe"
                                          }
                                          TouchSensor {
                                            type "force-3d"
                                            translation -0.060000 -0.007000 -0.034000
                                            rotation -0.000000 -0.000000 -1.000000 1.570800
                                            children [
                                              Wolfgang_llbMesh {
                                              }
                                              Solid {
                                                translation 0.000000 -0.000500 -0.016000
                                                rotation 0.000000 0.000000 1.000000 3.141590
                                                name "l_cleat_l_back"
                                              }
                                            ]
                                            name "llb"
                                            boundingObject Transform {
                                              translation 0.000000 0.000000 -0.008000
                                              rotation 0.000000 1.000000 0.000000 0.000000
                                              children [
                                                Box {
                                                  size 0.012000 0.012000 0.016000
                                                }
                                              ]
                                            }
                                            physics Physics {
                                              density -1
                                              mass 0.001660
                                              centerOfMass [ 0.000000 0.000156 -0.007759 ]
                                              inertiaMatrix [
                                                4.335200e-08 4.440490e-08 3.043970e-08
                                                -2.540260e-27 -3.401230e-27 -1.099300e-09
                                              ]
                                            }
                                          }
                                          TouchSensor {
                                            type "force-3d"
                                            translation -0.060000 0.177000 -0.034000
                                            rotation -0.000000 -0.000000 -1.000000 1.570800
                                            children [
                                              Wolfgang_llfMesh {
                                              }
                                              Solid {
                                                translation 0.000000 -0.000500 -0.016000
                                                rotation -0.000000 -0.000000 -1.000000 3.141590
                                                name "l_cleat_l_front"
                                              }
                                            ]
                                            name "llf"
                                            boundingObject Transform {
                                              translation 0.000000 0.000000 -0.008000
                                              rotation 0.000000 1.000000 0.000000 0.000000
                                              children [
                                                Box {
                                                  size 0.012000 0.012000 0.016000
                                                }
                                              ]
                                            }
                                            physics Physics {
                                              density -1
                                              mass 0.001660
                                              centerOfMass [ -0.000000 0.000156 -0.007759 ]
                                              inertiaMatrix [
                                                4.335200e-08 4.440490e-08 3.043970e-08
                                                2.251720e-27 8.036960e-25 -1.099300e-09
                                              ]
                                            }
                                          }
                                          TouchSensor {
                                            type "force-3d"
                                            translation 0.030000 0.177000 -0.034000
                                            rotation -0.000000 -0.000000 -1.000000 1.570800
                                            children [
                                              Wolfgang_lrfMesh {
                                              }
                                              Solid {
                                                translation 0.000000 -0.000500 -0.016000
                                                rotation -0.000000 -0.000000 -1.000000 3.141590
                                                name "l_cleat_r_front"
                                              }
                                            ]
                                            name "lrf"
                                            boundingObject Transform {
                                              translation 0.000000 0.000000 -0.008000
                                              rotation 0.000000 1.000000 0.000000 0.000000
                                              children [
                                                Box {
                                                  size 0.012000 0.012000 0.016000
                                                }
                                              ]
                                            }
                                            physics Physics {
                                              density -1
                                              mass 0.001660
                                              centerOfMass [ 0.000000 0.000156 -0.007759 ]
                                              inertiaMatrix [
                                                4.335200e-08 4.440490e-08 3.043970e-08
                                                2.251720e-27 8.036960e-25 -1.099300e-09
                                              ]
                                            }
                                          }
                                          TouchSensor {
                                            type "force-3d"
                                            translation 0.030000 -0.007000 -0.034000
                                            rotation -0.000000 -0.000000 -1.000000 1.570800
                                            children [
                                              Wolfgang_lrbMesh {
                                              }
                                              Solid {
                                                translation 0.000000 -0.000500 -0.016000
                                                rotation -0.000000 -0.000000 -1.000000 3.141590
                                                name "l_cleat_r_back"
                                              }
                                            ]
                                            name "lrb"
                                            boundingObject Transform {
                                              translation 0.000000 0.000000 -0.008000
                                              rotation 0.000000 1.000000 0.000000 0.000000
                                              children [
                                                Box {
                                                  size 0.012000 0.012000 0.016000
                                                }
                                              ]
                                            }
                                            physics Physics {
                                              density -1
                                              mass 0.001660
                                              centerOfMass [ -0.000000 0.000156 -0.007759 ]
                                              inertiaMatrix [
                                                4.335200e-08 4.440490e-08 3.043970e-08
                                                1.696600e-26 -1.091180e-24 -1.099300e-09
                                              ]
                                            }
                                          }
                                        ]
                                        name "l_foot"
                                        boundingObject Transform {
                                          translation -0.015000 0.085750 -0.012750
                                          rotation 0.000000 1.000000 0.000000 0.000000
                                          children [
                                            Box {
                                              size 0.106000 0.198500 0.053500
                                            }
                                          ]
                                        }
                                        physics Physics {
                                          density -1
                                          mass 0.268240
                                          centerOfMass [ -0.012040 0.091109 -0.029858 ]
                                          inertiaMatrix [
                                            8.841070e-04 3.173780e-04 1.153190e-03
                                            3.211040e-05 -5.092230e-06 -1.776930e-05
                                          ]
                                        }
                                      }
                                    }
                                  ]
                                  name "l_ankle"
                                  boundingObject Transform {
                                    translation 0.023250 -0.018050 -0.026500
                                    rotation 0.000000 1.000000 0.000000 0.000000
                                    children [
                                      Box {
                                        size 0.086700 0.065100 0.048000
                                      }
                                    ]
                                  }
                                  physics Physics {
                                    density -1
                                    mass 0.319807
                                    centerOfMass [ 0.020459 -0.015528 -0.026014 ]
                                    inertiaMatrix [
                                      1.167730e-04 2.684240e-04 2.728100e-04
                                      4.538570e-06 -6.750130e-07 -7.240730e-07
                                    ]
                                  }
                                }
                              }
                            ]
                            name "l_lower_leg"
                            boundingObject Transform {
                              translation 0.000074 -0.013500 -0.085000
                              rotation 0.000000 1.000000 0.000000 0.000000
                              children [
                                Box {
                                  size 0.048040 0.078000 0.206000
                                }
                              ]
                            }
                            physics Physics {
                              density -1
                              mass 0.088064
                              centerOfMass [ 0.001424 -0.018870 -0.061707 ]
                              inertiaMatrix [
                                2.849660e-04 2.389230e-04 7.617060e-05
                                -1.116610e-06 -8.911270e-06 -2.544810e-05
                              ]
                            }
                          }
                        }
                      ]
                      name "l_upper_leg"
                      boundingObject Transform {
                        translation -0.003376 -0.085039 0.035500
                        rotation 0.000000 1.000000 0.000000 0.000000
                        children [
                          Box {
                            size 0.068093 0.206075 0.079000
                          }
                        ]
                      }
                      physics Physics {
                        density -1
                        mass 0.242311
                        centerOfMass [ -0.004631 -0.132966 0.026322 ]
                        inertiaMatrix [
                          4.951120e-04 1.208280e-04 4.545970e-04
                          -2.807040e-05 2.533730e-06 4.334050e-06
                        ]
                      }
                    }
                  }
                ]
                name "l_hip_2"
                boundingObject Transform {
                  translation -0.000500 -0.018050 -0.045850
                  rotation 0.000000 1.000000 0.000000 0.000000
                  children [
                    Box {
                      size 0.048000 0.065100 0.086700
                    }
                  ]
                }
                physics Physics {
                  density -1
                  mass 0.319807
                  centerOfMass [ -0.000004 -0.015528 -0.048644 ]
                  inertiaMatrix [
                    2.686730e-04 2.680980e-04 1.213330e-04
                    -7.409920e-08 -6.187510e-07 3.883250e-06
                  ]
                }
              }
            }
          ]
          name "l_hip_1"
          boundingObject Transform {
            translation 0.000000 0.025987 0.000000
            rotation 0.000000 1.000000 0.000000 0.000000
            children [
              Box {
                size 0.100000 0.053175 0.050000
              }
            ]
          }
          physics Physics {
            density -1
            mass 0.068973
            centerOfMass [ 0.000000 0.010315 -0.000000 ]
            inertiaMatrix [
              2.189550e-05 1.071400e-04 1.105230e-04
              -2.444750e-14 3.067930e-15 -6.566880e-11
            ]
          }
        }
      }
      HingeJoint {
        jointParameters HingeJointParameters {
          axis 0.000000 -0.000003 1.000000
          anchor -0.009500 0.000000 0.234500
          dampingConstant 0.53
          staticFriction 0.0
        }
        device [
          RotationalMotor {
            name "HeadPan"
            maxVelocity 10.33
            minPosition -2.0944
            maxPosition 2.0944
            maxTorque 5.43
          }
          PositionSensor {
            name "HeadPan_sensor"
          }
        ]
        endPoint Solid {
          translation -0.009500 0.000000 0.234500
          rotation -1.000000 0.000000 0.000000 3.141590
          children [
            Wolfgang_neckMesh {
            }
            HingeJoint {
              jointParameters HingeJointParameters {
                axis 0.000000 1.000000 -0.000004
                anchor 0.036000 0.023500 -0.024000
                dampingConstant 0.53
                staticFriction 0.0
              }
              device [
                RotationalMotor {
                  name "HeadTilt"
                  maxVelocity 10.33
                  minPosition -1.5708
                  maxPosition 0.523599
                  maxTorque 5.43
                }
                PositionSensor {
                  name "HeadTilt_sensor"
                }
              ]
              endPoint Solid {
                translation 0.036000 0.023500 -0.024000
                rotation -1.000000 0.000000 -0.000000 1.570800
                children [
                  Wolfgang_headMesh {
                  }
                  Solid {
                    translation 0.043700 0.079500 -0.023500
                    rotation -1.000000 -0.000000 -0.000000 1.570800
                    name "camera"
                  }
                  Solid {
                    translation 0.043200 0.080000 -0.023500
                    rotation 0.707105 -0.000001 0.707108 3.141591
                    children [
                      Camera {
                        rotation 1.0 0.0 0.0 3.141591
                        name "camera"
                        fieldOfView 0.570000
                        width 620
                        height 480
                      }
                    ]
                    name "camera_optical_frame"
                  }
                  Solid {
                    translation -0.025450 0.053500 -0.023500
                    rotation -1.000000 -0.000000 -0.000000 1.570800
                    children [
                      Accelerometer {
                        name "imu_head accelerometer"
                      }
                      Gyro {
                        name "imu_head gyro"
                      }
                      Compass {
                        name "imu_head compass"
                      }
                      Solid {
                        translation -0.050000 0.020000 -0.030000
                        rotation -1.000000 0.000000 0.000000 1.570800
                        name "imu_frame_2_2"
                      }
                    ]
                    name "imu_frame_2"
                  }
                ]
                name "head"
                boundingObject Transform {
                  translation 0.001500 0.040000 -0.017000
                  rotation 0.000000 1.000000 0.000000 0.000000
                  children [
                    Box {
                      size 0.127000 0.130000 0.073000
                    }
                  ]
                }
                physics Physics {
                  density -1
                  mass 0.301358
                  centerOfMass [ 0.000412 0.067494 -0.020065 ]
                  inertiaMatrix [
                    3.442650e-04 3.337130e-04 4.218980e-04
                    -2.072630e-05 1.058260e-06 5.117220e-05
                  ]
                }
              }
            }
          ]
          name "neck"
          boundingObject Transform {
            translation 0.017250 0.001050 -0.022050
            rotation 0.000000 1.000000 0.000000 0.000000
            children [
              Box {
                size 0.063500 0.046100 0.044100
              }
            ]
          }
          physics Physics {
            density -1
            mass 0.148233
            centerOfMass [ 0.018691 -0.000078 -0.022014 ]
            inertiaMatrix [
              3.893550e-05 5.763180e-05 6.254140e-05
              -5.287090e-07 4.956980e-06 -2.281580e-08
            ]
          }
        }
      }
    ]
    name IS name 
    boundingObject Transform {
      translation -0.002000 0.000000 0.117750
      rotation 0.000000 1.000000 0.000000 0.000000
      children [
        Box {
          size 0.190111 0.154000 0.230500
        }
      ]
    }
    physics Physics {
      density -1
      mass 2.083900
      centerOfMass [ -0.005644 -0.002630 0.109553 ]
      inertiaMatrix [
        1.838960e-02 1.587720e-02 7.803170e-03
        -6.801730e-05 -1.408270e-03 1.040740e-04
      ]
    }
  }
}
